07.14.2016 08:03:19 TMV3 Measurement started Meas
07.14.2016 08:03:19 VI_ERROR_RSRC_NFOUND (-1073807343): Insufficient location information or the requested device or resource is not present in the system. Meas
Traceback (most recent call last):
  File "C:\TMV3\DeviceDriver\DD_Analyzer.py", line 34, in checkConnection
    self.sa = self.rm.open_resource(self.name)
  File "C:\Python34\lib\site-packages\pyvisa\highlevel.py", line 1614, in open_resource
    info = self.resource_info(resource_name)
  File "C:\Python34\lib\site-packages\pyvisa\highlevel.py", line 1581, in resource_info
    ret, err = self.visalib.parse_resource_extended(self.session, resource_name)
  File "C:\Python34\lib\site-packages\pyvisa\ctwrapper\functions.py", line 1378, in parse_resource_extended
    alias_if_exists)
  File "C:\Python34\lib\site-packages\pyvisa\ctwrapper\highlevel.py", line 188, in _return_handler
    raise errors.VisaIOError(ret_value)
pyvisa.errors.VisaIOError: VI_ERROR_RSRC_NFOUND (-1073807343): Insufficient location information or the requested device or resource is not present in the system.
07.14.2016 08:03:21 VI_ERROR_RSRC_NFOUND (-1073807343): Insufficient location information or the requested device or resource is not present in the system. Meas
Traceback (most recent call last):
  File "C:\TMV3\DeviceDriver\DD_Analyzer.py", line 34, in checkConnection
    self.sa = self.rm.open_resource(self.name)
  File "C:\Python34\lib\site-packages\pyvisa\highlevel.py", line 1634, in open_resource
    res.open(access_mode, open_timeout)
  File "C:\Python34\lib\site-packages\pyvisa\resources\resource.py", line 184, in open
    self.session, status = self._resource_manager.open_bare_resource(self._resource_name, access_mode, open_timeout)
  File "C:\Python34\lib\site-packages\pyvisa\highlevel.py", line 1598, in open_bare_resource
    return self.visalib.open(self.session, resource_name, access_mode, open_timeout)
  File "C:\Python34\lib\site-packages\pyvisa\ctwrapper\functions.py", line 1208, in open
    ret = library.viOpen(session, resource_name, access_mode, open_timeout, byref(out_session))
  File "C:\Python34\lib\site-packages\pyvisa\ctwrapper\highlevel.py", line 188, in _return_handler
    raise errors.VisaIOError(ret_value)
pyvisa.errors.VisaIOError: VI_ERROR_RSRC_NFOUND (-1073807343): Insufficient location information or the requested device or resource is not present in the system.
