08.16.2017 10:52:46 near "WHERE": syntax error Server
Traceback (most recent call last):
  File "C:\TMV3\Lib\DB_Handler_TPL3.py", line 1655, in read
    _cur.execute (_s)
sqlite3.OperationalError: near "WHERE": syntax error
08.16.2017 10:54:12 near "WHERE": syntax error Server
Traceback (most recent call last):
  File "C:\TMV3\Lib\DB_Handler_TPL3.py", line 1656, in read
    _cur.execute (_s)
sqlite3.OperationalError: near "WHERE": syntax error
08.16.2017 10:55:59 near "WHERE": syntax error Server
Traceback (most recent call last):
  File "C:\TMV3\Lib\DB_Handler_TPL3.py", line 1656, in read
    _cur.execute (_s)
sqlite3.OperationalError: near "WHERE": syntax error
08.23.2017 10:28:48 'NoneType' object is not subscriptable Server
Traceback (most recent call last):
  File "C:\TMV3\Lib\DB_Handler_TPL3.py", line 565, in export
    output_file.write(_file[0])
TypeError: 'NoneType' object is not subscriptable
08.23.2017 10:28:51 no such table: Plan Server
Traceback (most recent call last):
  File "C:\TMV3\Lib\DB_Handler_TDS3.py", line 768, in read
    _cur.execute ("SELECT * FROM [Plan]")
sqlite3.OperationalError: no such table: Plan
08.23.2017 10:35:30 TMV3 Measurement started Meas
08.23.2017 10:35:30 [Errno 2] No such file or directory: 'C:\\TMV3\\WorkingDir\\RT_ZoneZZ.py' Meas
Traceback (most recent call last):
  File "Measurement.py", line 270, in parser
    _py_mod = _loader.load_module()
  File "<frozen importlib._bootstrap>", line 539, in _check_name_wrapper
  File "<frozen importlib._bootstrap>", line 1614, in load_module
  File "<frozen importlib._bootstrap>", line 596, in _load_module_shim
  File "<frozen importlib._bootstrap>", line 1220, in load
  File "<frozen importlib._bootstrap>", line 1200, in _load_unlocked
  File "<frozen importlib._bootstrap>", line 1129, in _exec
  File "<frozen importlib._bootstrap>", line 1467, in exec_module
  File "<frozen importlib._bootstrap>", line 1571, in get_code
  File "<frozen importlib._bootstrap>", line 1623, in get_data
FileNotFoundError: [Errno 2] No such file or directory: 'C:\\TMV3\\WorkingDir\\RT_ZoneZZ.py'
08.23.2017 10:39:29 recv 2fd1680 error WSAECONNRESET Server
08.23.2017 10:39:30 recv 1fd1108 error WSAECONNRESET Server
08.23.2017 10:39:31 TMV3 Measurement started Meas
08.23.2017 10:39:31 [Errno 2] No such file or directory: 'C:\\TMV3\\WorkingDir\\DD_FSWT.py' Meas
Traceback (most recent call last):
  File "C:\TMV3\Routines\RT_StandardHF.py", line 126, in loadDriver
    _py_mod = _loader.load_module()
  File "<frozen importlib._bootstrap>", line 539, in _check_name_wrapper
  File "<frozen importlib._bootstrap>", line 1614, in load_module
  File "<frozen importlib._bootstrap>", line 596, in _load_module_shim
  File "<frozen importlib._bootstrap>", line 1220, in load
  File "<frozen importlib._bootstrap>", line 1200, in _load_unlocked
  File "<frozen importlib._bootstrap>", line 1129, in _exec
  File "<frozen importlib._bootstrap>", line 1467, in exec_module
  File "<frozen importlib._bootstrap>", line 1571, in get_code
  File "<frozen importlib._bootstrap>", line 1623, in get_data
FileNotFoundError: [Errno 2] No such file or directory: 'C:\\TMV3\\WorkingDir\\DD_FSWT.py'
08.23.2017 10:39:31 [Errno 2] No such file or directory: 'C:\\TMV3\\WorkingDir\\DD_FSET.py' Meas
Traceback (most recent call last):
  File "C:\TMV3\Routines\RT_StandardHF.py", line 126, in loadDriver
    _py_mod = _loader.load_module()
  File "<frozen importlib._bootstrap>", line 539, in _check_name_wrapper
  File "<frozen importlib._bootstrap>", line 1614, in load_module
  File "<frozen importlib._bootstrap>", line 596, in _load_module_shim
  File "<frozen importlib._bootstrap>", line 1220, in load
  File "<frozen importlib._bootstrap>", line 1200, in _load_unlocked
  File "<frozen importlib._bootstrap>", line 1129, in _exec
  File "<frozen importlib._bootstrap>", line 1467, in exec_module
  File "<frozen importlib._bootstrap>", line 1571, in get_code
  File "<frozen importlib._bootstrap>", line 1623, in get_data
FileNotFoundError: [Errno 2] No such file or directory: 'C:\\TMV3\\WorkingDir\\DD_FSET.py'
08.23.2017 10:40:47 recv 4fd1700 error WSAECONNRESET Server
08.23.2017 10:40:48 recv 3fd1136 error WSAECONNRESET Server
08.23.2017 10:40:49 TMV3 Measurement started Meas
08.23.2017 10:40:50 [Errno 2] No such file or directory: 'C:\\TMV3\\WorkingDir\\DD_FSWT.py' Meas
Traceback (most recent call last):
  File "C:\TMV3\Routines\RT_StandardHF.py", line 126, in loadDriver
    _py_mod = _loader.load_module()
  File "<frozen importlib._bootstrap>", line 539, in _check_name_wrapper
  File "<frozen importlib._bootstrap>", line 1614, in load_module
  File "<frozen importlib._bootstrap>", line 596, in _load_module_shim
  File "<frozen importlib._bootstrap>", line 1220, in load
  File "<frozen importlib._bootstrap>", line 1200, in _load_unlocked
  File "<frozen importlib._bootstrap>", line 1129, in _exec
  File "<frozen importlib._bootstrap>", line 1467, in exec_module
  File "<frozen importlib._bootstrap>", line 1571, in get_code
  File "<frozen importlib._bootstrap>", line 1623, in get_data
FileNotFoundError: [Errno 2] No such file or directory: 'C:\\TMV3\\WorkingDir\\DD_FSWT.py'
08.23.2017 10:40:50 VI_ERROR_RSRC_NFOUND (-1073807343): Insufficient location information or the requested device or resource is not present in the system. Meas
Traceback (most recent call last):
  File "C:\TMV3\DeviceDriver\DD_Analyzer.py", line 52, in checkConnection
    self.sa = self.rm.open_resource(self.name)
  File "C:\Python34\lib\site-packages\pyvisa\highlevel.py", line 1623, in open_resource
    info = self.resource_info(resource_name, extended=True)
  File "C:\Python34\lib\site-packages\pyvisa\highlevel.py", line 1583, in resource_info
    ret, err = self.visalib.parse_resource_extended(self.session, resource_name)
  File "C:\Python34\lib\site-packages\pyvisa\ctwrapper\functions.py", line 1381, in parse_resource_extended
    alias_if_exists)
  File "C:\Python34\lib\site-packages\pyvisa\ctwrapper\highlevel.py", line 188, in _return_handler
    raise errors.VisaIOError(ret_value)
pyvisa.errors.VisaIOError: VI_ERROR_RSRC_NFOUND (-1073807343): Insufficient location information or the requested device or resource is not present in the system.
08.23.2017 02:50:26 recv 5fd236 error WSAECONNRESET Server
08.24.2017 09:09:01 TMV3 Measurement started Meas
08.24.2017 09:09:02 [Errno 2] No such file or directory: 'C:\\TMV3\\WorkingDir\\DD_FSWT.py' Meas
Traceback (most recent call last):
  File "C:\TMV3\Routines\RT_StandardHF.py", line 126, in loadDriver
    _py_mod = _loader.load_module()
  File "<frozen importlib._bootstrap>", line 539, in _check_name_wrapper
  File "<frozen importlib._bootstrap>", line 1614, in load_module
  File "<frozen importlib._bootstrap>", line 596, in _load_module_shim
  File "<frozen importlib._bootstrap>", line 1220, in load
  File "<frozen importlib._bootstrap>", line 1200, in _load_unlocked
  File "<frozen importlib._bootstrap>", line 1129, in _exec
  File "<frozen importlib._bootstrap>", line 1467, in exec_module
  File "<frozen importlib._bootstrap>", line 1571, in get_code
  File "<frozen importlib._bootstrap>", line 1623, in get_data
FileNotFoundError: [Errno 2] No such file or directory: 'C:\\TMV3\\WorkingDir\\DD_FSWT.py'
08.24.2017 09:09:04 float() takes at most 1 argument (7 given) Meas
Traceback (most recent call last):
  File "C:\TMV3\Routines\RT_StandardHF.py", line 316, in startSetting
    _ret = _func(row.parameter)
  File "C:\TMV3\WorkingDir\DD_FSET.py", line 44, in set_StartFreq
    f = float(*par[0])
TypeError: float() takes at most 1 argument (7 given)
08.24.2017 09:13:31 TMV3 Measurement started Meas
08.24.2017 09:13:31 [Errno 2] No such file or directory: 'C:\\TMV3\\WorkingDir\\DD_FSWT.py' Meas
Traceback (most recent call last):
  File "C:\TMV3\Routines\RT_StandardHF.py", line 126, in loadDriver
    _py_mod = _loader.load_module()
  File "<frozen importlib._bootstrap>", line 539, in _check_name_wrapper
  File "<frozen importlib._bootstrap>", line 1614, in load_module
  File "<frozen importlib._bootstrap>", line 596, in _load_module_shim
  File "<frozen importlib._bootstrap>", line 1220, in load
  File "<frozen importlib._bootstrap>", line 1200, in _load_unlocked
  File "<frozen importlib._bootstrap>", line 1129, in _exec
  File "<frozen importlib._bootstrap>", line 1467, in exec_module
  File "<frozen importlib._bootstrap>", line 1571, in get_code
  File "<frozen importlib._bootstrap>", line 1623, in get_data
FileNotFoundError: [Errno 2] No such file or directory: 'C:\\TMV3\\WorkingDir\\DD_FSWT.py'
08.24.2017 09:13:34 -178,"Expression data not allowed;SENSE:BAND ('5000.0',)"
 Meas
08.24.2017 09:15:46 TMV3 Measurement started Meas
08.24.2017 09:15:46 [Errno 2] No such file or directory: 'C:\\TMV3\\WorkingDir\\DD_FSWT.py' Meas
Traceback (most recent call last):
  File "C:\TMV3\Routines\RT_StandardHF.py", line 126, in loadDriver
    _py_mod = _loader.load_module()
  File "<frozen importlib._bootstrap>", line 539, in _check_name_wrapper
  File "<frozen importlib._bootstrap>", line 1614, in load_module
  File "<frozen importlib._bootstrap>", line 596, in _load_module_shim
  File "<frozen importlib._bootstrap>", line 1220, in load
  File "<frozen importlib._bootstrap>", line 1200, in _load_unlocked
  File "<frozen importlib._bootstrap>", line 1129, in _exec
  File "<frozen importlib._bootstrap>", line 1467, in exec_module
  File "<frozen importlib._bootstrap>", line 1571, in get_code
  File "<frozen importlib._bootstrap>", line 1623, in get_data
FileNotFoundError: [Errno 2] No such file or directory: 'C:\\TMV3\\WorkingDir\\DD_FSWT.py'
08.24.2017 09:15:49 -178,"Expression data not allowed;INP:PRES:SET ('NORMAL',)"
 Meas
08.24.2017 09:15:56 recv 2fd1620 error WSAECONNRESET Server
08.24.2017 09:16:58 TMV3 Measurement started Meas
08.24.2017 09:16:58 [Errno 2] No such file or directory: 'C:\\TMV3\\WorkingDir\\DD_FSWT.py' Meas
Traceback (most recent call last):
  File "C:\TMV3\Routines\RT_StandardHF.py", line 126, in loadDriver
    _py_mod = _loader.load_module()
  File "<frozen importlib._bootstrap>", line 539, in _check_name_wrapper
  File "<frozen importlib._bootstrap>", line 1614, in load_module
  File "<frozen importlib._bootstrap>", line 596, in _load_module_shim
  File "<frozen importlib._bootstrap>", line 1220, in load
  File "<frozen importlib._bootstrap>", line 1200, in _load_unlocked
  File "<frozen importlib._bootstrap>", line 1129, in _exec
  File "<frozen importlib._bootstrap>", line 1467, in exec_module
  File "<frozen importlib._bootstrap>", line 1571, in get_code
  File "<frozen importlib._bootstrap>", line 1623, in get_data
FileNotFoundError: [Errno 2] No such file or directory: 'C:\\TMV3\\WorkingDir\\DD_FSWT.py'
08.24.2017 09:17:01 -178,"Expression data not allowed;DISP:TRAC:Y:RLEV ('87.0',)"
 Meas
08.24.2017 09:17:10 recv 2fd1644 error WSAECONNRESET Server
08.24.2017 09:20:49 TMV3 Measurement started Meas
08.24.2017 09:20:49 [Errno 2] No such file or directory: 'C:\\TMV3\\WorkingDir\\DD_FSWT.py' Meas
Traceback (most recent call last):
  File "C:\TMV3\Routines\RT_StandardHF.py", line 126, in loadDriver
    _py_mod = _loader.load_module()
  File "<frozen importlib._bootstrap>", line 539, in _check_name_wrapper
  File "<frozen importlib._bootstrap>", line 1614, in load_module
  File "<frozen importlib._bootstrap>", line 596, in _load_module_shim
  File "<frozen importlib._bootstrap>", line 1220, in load
  File "<frozen importlib._bootstrap>", line 1200, in _load_unlocked
  File "<frozen importlib._bootstrap>", line 1129, in _exec
  File "<frozen importlib._bootstrap>", line 1467, in exec_module
  File "<frozen importlib._bootstrap>", line 1571, in get_code
  File "<frozen importlib._bootstrap>", line 1623, in get_data
FileNotFoundError: [Errno 2] No such file or directory: 'C:\\TMV3\\WorkingDir\\DD_FSWT.py'
08.24.2017 09:20:52 -178,"Expression data not allowed;SENSE:SWEEP:TIME ('20.0',)S"
 Meas
08.24.2017 09:21:01 recv 2fd1648 error WSAECONNRESET Server
08.24.2017 09:22:00 TMV3 Measurement started Meas
08.24.2017 09:22:01 [Errno 2] No such file or directory: 'C:\\TMV3\\WorkingDir\\DD_FSWT.py' Meas
Traceback (most recent call last):
  File "C:\TMV3\Routines\RT_StandardHF.py", line 126, in loadDriver
    _py_mod = _loader.load_module()
  File "<frozen importlib._bootstrap>", line 539, in _check_name_wrapper
  File "<frozen importlib._bootstrap>", line 1614, in load_module
  File "<frozen importlib._bootstrap>", line 596, in _load_module_shim
  File "<frozen importlib._bootstrap>", line 1220, in load
  File "<frozen importlib._bootstrap>", line 1200, in _load_unlocked
  File "<frozen importlib._bootstrap>", line 1129, in _exec
  File "<frozen importlib._bootstrap>", line 1467, in exec_module
  File "<frozen importlib._bootstrap>", line 1571, in get_code
  File "<frozen importlib._bootstrap>", line 1623, in get_data
FileNotFoundError: [Errno 2] No such file or directory: 'C:\\TMV3\\WorkingDir\\DD_FSWT.py'
08.24.2017 09:22:05 -256,"File name not found;CORR:TSET:DEL"
 Meas
08.24.2017 09:23:28 [Errno 2] No such file or directory: 'C:\\TMV3\\WorkingDir\\DD_FSWT.py' Meas
Traceback (most recent call last):
  File "C:\TMV3\Routines\RT_StandardHF.py", line 126, in loadDriver
    _py_mod = _loader.load_module()
  File "<frozen importlib._bootstrap>", line 539, in _check_name_wrapper
  File "<frozen importlib._bootstrap>", line 1614, in load_module
  File "<frozen importlib._bootstrap>", line 596, in _load_module_shim
  File "<frozen importlib._bootstrap>", line 1220, in load
  File "<frozen importlib._bootstrap>", line 1200, in _load_unlocked
  File "<frozen importlib._bootstrap>", line 1129, in _exec
  File "<frozen importlib._bootstrap>", line 1467, in exec_module
  File "<frozen importlib._bootstrap>", line 1571, in get_code
  File "<frozen importlib._bootstrap>", line 1623, in get_data
FileNotFoundError: [Errno 2] No such file or directory: 'C:\\TMV3\\WorkingDir\\DD_FSWT.py'
08.24.2017 09:25:10 -256,"File name not found;CORR:TSET:DEL"
 Meas
08.24.2017 09:30:53 [Errno 2] No such file or directory: 'C:\\TMV3\\WorkingDir\\DD_FSWT.py' Meas
Traceback (most recent call last):
  File "C:\TMV3\Routines\RT_StandardHF.py", line 126, in loadDriver
    _py_mod = _loader.load_module()
  File "<frozen importlib._bootstrap>", line 539, in _check_name_wrapper
  File "<frozen importlib._bootstrap>", line 1614, in load_module
  File "<frozen importlib._bootstrap>", line 596, in _load_module_shim
  File "<frozen importlib._bootstrap>", line 1220, in load
  File "<frozen importlib._bootstrap>", line 1200, in _load_unlocked
  File "<frozen importlib._bootstrap>", line 1129, in _exec
  File "<frozen importlib._bootstrap>", line 1467, in exec_module
  File "<frozen importlib._bootstrap>", line 1571, in get_code
  File "<frozen importlib._bootstrap>", line 1623, in get_data
FileNotFoundError: [Errno 2] No such file or directory: 'C:\\TMV3\\WorkingDir\\DD_FSWT.py'
08.24.2017 09:36:00 [Errno 2] No such file or directory: 'C:\\TMV3\\WorkingDir\\DD_FSWT.py' Meas
Traceback (most recent call last):
  File "C:\TMV3\Routines\RT_StandardHF.py", line 126, in loadDriver
    _py_mod = _loader.load_module()
  File "<frozen importlib._bootstrap>", line 539, in _check_name_wrapper
  File "<frozen importlib._bootstrap>", line 1614, in load_module
  File "<frozen importlib._bootstrap>", line 596, in _load_module_shim
  File "<frozen importlib._bootstrap>", line 1220, in load
  File "<frozen importlib._bootstrap>", line 1200, in _load_unlocked
  File "<frozen importlib._bootstrap>", line 1129, in _exec
  File "<frozen importlib._bootstrap>", line 1467, in exec_module
  File "<frozen importlib._bootstrap>", line 1571, in get_code
  File "<frozen importlib._bootstrap>", line 1623, in get_data
FileNotFoundError: [Errno 2] No such file or directory: 'C:\\TMV3\\WorkingDir\\DD_FSWT.py'
08.24.2017 09:39:27 [Errno 2] No such file or directory: 'C:\\TMV3\\WorkingDir\\DD_FSWT.py' Meas
Traceback (most recent call last):
  File "C:\TMV3\Routines\RT_StandardHF.py", line 126, in loadDriver
    _py_mod = _loader.load_module()
  File "<frozen importlib._bootstrap>", line 539, in _check_name_wrapper
  File "<frozen importlib._bootstrap>", line 1614, in load_module
  File "<frozen importlib._bootstrap>", line 596, in _load_module_shim
  File "<frozen importlib._bootstrap>", line 1220, in load
  File "<frozen importlib._bootstrap>", line 1200, in _load_unlocked
  File "<frozen importlib._bootstrap>", line 1129, in _exec
  File "<frozen importlib._bootstrap>", line 1467, in exec_module
  File "<frozen importlib._bootstrap>", line 1571, in get_code
  File "<frozen importlib._bootstrap>", line 1623, in get_data
FileNotFoundError: [Errno 2] No such file or directory: 'C:\\TMV3\\WorkingDir\\DD_FSWT.py'
08.24.2017 09:42:06 [Errno 2] No such file or directory: 'C:\\TMV3\\WorkingDir\\DD_FSWT.py' Meas
Traceback (most recent call last):
  File "C:\TMV3\Routines\RT_StandardHF.py", line 126, in loadDriver
    _py_mod = _loader.load_module()
  File "<frozen importlib._bootstrap>", line 539, in _check_name_wrapper
  File "<frozen importlib._bootstrap>", line 1614, in load_module
  File "<frozen importlib._bootstrap>", line 596, in _load_module_shim
  File "<frozen importlib._bootstrap>", line 1220, in load
  File "<frozen importlib._bootstrap>", line 1200, in _load_unlocked
  File "<frozen importlib._bootstrap>", line 1129, in _exec
  File "<frozen importlib._bootstrap>", line 1467, in exec_module
  File "<frozen importlib._bootstrap>", line 1571, in get_code
  File "<frozen importlib._bootstrap>", line 1623, in get_data
FileNotFoundError: [Errno 2] No such file or directory: 'C:\\TMV3\\WorkingDir\\DD_FSWT.py'
08.24.2017 09:44:02 [Errno 2] No such file or directory: 'C:\\TMV3\\WorkingDir\\DD_FSWT.py' Meas
Traceback (most recent call last):
  File "C:\TMV3\Routines\RT_StandardHF.py", line 126, in loadDriver
    _py_mod = _loader.load_module()
  File "<frozen importlib._bootstrap>", line 539, in _check_name_wrapper
  File "<frozen importlib._bootstrap>", line 1614, in load_module
  File "<frozen importlib._bootstrap>", line 596, in _load_module_shim
  File "<frozen importlib._bootstrap>", line 1220, in load
  File "<frozen importlib._bootstrap>", line 1200, in _load_unlocked
  File "<frozen importlib._bootstrap>", line 1129, in _exec
  File "<frozen importlib._bootstrap>", line 1467, in exec_module
  File "<frozen importlib._bootstrap>", line 1571, in get_code
  File "<frozen importlib._bootstrap>", line 1623, in get_data
FileNotFoundError: [Errno 2] No such file or directory: 'C:\\TMV3\\WorkingDir\\DD_FSWT.py'
08.24.2017 09:45:11 [Errno 2] No such file or directory: 'C:\\TMV3\\WorkingDir\\DD_FSWT.py' Meas
Traceback (most recent call last):
  File "C:\TMV3\Routines\RT_StandardHF.py", line 126, in loadDriver
    _py_mod = _loader.load_module()
  File "<frozen importlib._bootstrap>", line 539, in _check_name_wrapper
  File "<frozen importlib._bootstrap>", line 1614, in load_module
  File "<frozen importlib._bootstrap>", line 596, in _load_module_shim
  File "<frozen importlib._bootstrap>", line 1220, in load
  File "<frozen importlib._bootstrap>", line 1200, in _load_unlocked
  File "<frozen importlib._bootstrap>", line 1129, in _exec
  File "<frozen importlib._bootstrap>", line 1467, in exec_module
  File "<frozen importlib._bootstrap>", line 1571, in get_code
  File "<frozen importlib._bootstrap>", line 1623, in get_data
FileNotFoundError: [Errno 2] No such file or directory: 'C:\\TMV3\\WorkingDir\\DD_FSWT.py'
08.24.2017 09:45:41 [Errno 2] No such file or directory: 'C:\\TMV3\\WorkingDir\\DD_FSWT.py' Meas
Traceback (most recent call last):
  File "C:\TMV3\Routines\RT_StandardHF.py", line 126, in loadDriver
    _py_mod = _loader.load_module()
  File "<frozen importlib._bootstrap>", line 539, in _check_name_wrapper
  File "<frozen importlib._bootstrap>", line 1614, in load_module
  File "<frozen importlib._bootstrap>", line 596, in _load_module_shim
  File "<frozen importlib._bootstrap>", line 1220, in load
  File "<frozen importlib._bootstrap>", line 1200, in _load_unlocked
  File "<frozen importlib._bootstrap>", line 1129, in _exec
  File "<frozen importlib._bootstrap>", line 1467, in exec_module
  File "<frozen importlib._bootstrap>", line 1571, in get_code
  File "<frozen importlib._bootstrap>", line 1623, in get_data
FileNotFoundError: [Errno 2] No such file or directory: 'C:\\TMV3\\WorkingDir\\DD_FSWT.py'
08.24.2017 09:45:47 -256,"File name not found;CORR:TSET:DEL"
 Meas
08.24.2017 09:46:11 unorderable types: str() >= float()
Traceback (most recent call last):
  File "Graph.py", line 1207, in onNewTrace
    self.addAmp(_startFreq,_stopFreq,data.amplifier,data.autorange)
  File "Graph.py", line 938, in addAmp
    _sAMP = form.FloatToString(amp,0)
  File "C:\TMV3\Lib\EngFormat.py", line 8, in FloatToString
    if value >= 1e9:
TypeError: unorderable types: str() >= float()
08.24.2017 09:46:13 -222,"Data out of range;SENSE:FREQ:START 4000000000.0H"
 Meas
08.24.2017 09:55:20 recv 2fd1628 error WSAECONNRESET Server
08.24.2017 09:59:21 TMV3 Measurement started Meas
08.24.2017 09:59:22 [Errno 2] No such file or directory: 'C:\\TMV3\\WorkingDir\\DD_FSWT.py' Meas
Traceback (most recent call last):
  File "C:\TMV3\Routines\RT_StandardHF.py", line 126, in loadDriver
    _py_mod = _loader.load_module()
  File "<frozen importlib._bootstrap>", line 539, in _check_name_wrapper
  File "<frozen importlib._bootstrap>", line 1614, in load_module
  File "<frozen importlib._bootstrap>", line 596, in _load_module_shim
  File "<frozen importlib._bootstrap>", line 1220, in load
  File "<frozen importlib._bootstrap>", line 1200, in _load_unlocked
  File "<frozen importlib._bootstrap>", line 1129, in _exec
  File "<frozen importlib._bootstrap>", line 1467, in exec_module
  File "<frozen importlib._bootstrap>", line 1571, in get_code
  File "<frozen importlib._bootstrap>", line 1623, in get_data
FileNotFoundError: [Errno 2] No such file or directory: 'C:\\TMV3\\WorkingDir\\DD_FSWT.py'
08.24.2017 09:59:52 unorderable types: str() >= float()
Traceback (most recent call last):
  File "Graph.py", line 1207, in onNewTrace
    self.addAmp(_startFreq,_stopFreq,data.amplifier,data.autorange)
  File "Graph.py", line 938, in addAmp
    _sAMP = form.FloatToString(amp,0)
  File "C:\TMV3\Lib\EngFormat.py", line 8, in FloatToString
    if value >= 1e9:
TypeError: unorderable types: str() >= float()
08.24.2017 09:59:54 -222,"Data out of range;SENSE:FREQ:START 4000000000.0H"
 Meas
08.24.2017 10:04:21 TMV3 Measurement started Meas
08.24.2017 10:04:23 [Errno 2] No such file or directory: 'C:\\TMV3\\WorkingDir\\DD_FSWT.py' Meas
Traceback (most recent call last):
  File "C:\TMV3\Routines\RT_StandardHF.py", line 126, in loadDriver
    _py_mod = _loader.load_module()
  File "<frozen importlib._bootstrap>", line 539, in _check_name_wrapper
  File "<frozen importlib._bootstrap>", line 1614, in load_module
  File "<frozen importlib._bootstrap>", line 596, in _load_module_shim
  File "<frozen importlib._bootstrap>", line 1220, in load
  File "<frozen importlib._bootstrap>", line 1200, in _load_unlocked
  File "<frozen importlib._bootstrap>", line 1129, in _exec
  File "<frozen importlib._bootstrap>", line 1467, in exec_module
  File "<frozen importlib._bootstrap>", line 1571, in get_code
  File "<frozen importlib._bootstrap>", line 1623, in get_data
FileNotFoundError: [Errno 2] No such file or directory: 'C:\\TMV3\\WorkingDir\\DD_FSWT.py'
08.24.2017 10:04:55 unorderable types: str() >= float()
Traceback (most recent call last):
  File "Graph.py", line 1207, in onNewTrace
    self.addAmp(_startFreq,_stopFreq,data.amplifier,data.autorange)
  File "Graph.py", line 938, in addAmp
    _sAMP = form.FloatToString(amp,0)
  File "C:\TMV3\Lib\EngFormat.py", line 8, in FloatToString
    if value >= 1e9:
TypeError: unorderable types: str() >= float()
08.24.2017 10:04:57 -222,"Data out of range;SENSE:FREQ:START 4000000000.0H"
 Meas
08.24.2017 10:09:05 TMV3 Measurement started Meas
08.24.2017 10:09:07 [Errno 2] No such file or directory: 'C:\\TMV3\\WorkingDir\\DD_FSWT.py' Meas
Traceback (most recent call last):
  File "C:\TMV3\Routines\RT_StandardHF.py", line 126, in loadDriver
    _py_mod = _loader.load_module()
  File "<frozen importlib._bootstrap>", line 539, in _check_name_wrapper
  File "<frozen importlib._bootstrap>", line 1614, in load_module
  File "<frozen importlib._bootstrap>", line 596, in _load_module_shim
  File "<frozen importlib._bootstrap>", line 1220, in load
  File "<frozen importlib._bootstrap>", line 1200, in _load_unlocked
  File "<frozen importlib._bootstrap>", line 1129, in _exec
  File "<frozen importlib._bootstrap>", line 1467, in exec_module
  File "<frozen importlib._bootstrap>", line 1571, in get_code
  File "<frozen importlib._bootstrap>", line 1623, in get_data
FileNotFoundError: [Errno 2] No such file or directory: 'C:\\TMV3\\WorkingDir\\DD_FSWT.py'
08.24.2017 10:09:37 unorderable types: str() >= float()
Traceback (most recent call last):
  File "Graph.py", line 1207, in onNewTrace
    self.addAmp(_startFreq,_stopFreq,data.amplifier,data.autorange)
  File "Graph.py", line 938, in addAmp
    _sAMP = form.FloatToString(amp,0)
  File "C:\TMV3\Lib\EngFormat.py", line 8, in FloatToString
    if value >= 1e9:
TypeError: unorderable types: str() >= float()
08.24.2017 10:09:38 -222,"Data out of range;SENSE:FREQ:START 4000000000.0H"
 Meas
08.24.2017 10:14:35 TMV3 Measurement started Meas
08.24.2017 10:14:37 [Errno 2] No such file or directory: 'C:\\TMV3\\WorkingDir\\DD_FSWT.py' Meas
Traceback (most recent call last):
  File "C:\TMV3\Routines\RT_StandardHF.py", line 126, in loadDriver
    _py_mod = _loader.load_module()
  File "<frozen importlib._bootstrap>", line 539, in _check_name_wrapper
  File "<frozen importlib._bootstrap>", line 1614, in load_module
  File "<frozen importlib._bootstrap>", line 596, in _load_module_shim
  File "<frozen importlib._bootstrap>", line 1220, in load
  File "<frozen importlib._bootstrap>", line 1200, in _load_unlocked
  File "<frozen importlib._bootstrap>", line 1129, in _exec
  File "<frozen importlib._bootstrap>", line 1467, in exec_module
  File "<frozen importlib._bootstrap>", line 1571, in get_code
  File "<frozen importlib._bootstrap>", line 1623, in get_data
FileNotFoundError: [Errno 2] No such file or directory: 'C:\\TMV3\\WorkingDir\\DD_FSWT.py'
08.24.2017 10:15:08 unorderable types: str() >= float()
Traceback (most recent call last):
  File "Graph.py", line 1207, in onNewTrace
    self.addAmp(_startFreq,_stopFreq,data.amplifier,data.autorange)
  File "Graph.py", line 938, in addAmp
    _sAMP = form.FloatToString(amp,0)
  File "C:\TMV3\Lib\EngFormat.py", line 8, in FloatToString
    if value >= 1e9:
TypeError: unorderable types: str() >= float()
08.24.2017 10:15:21 unorderable types: str() >= float()
Traceback (most recent call last):
  File "Graph.py", line 1207, in onNewTrace
    self.addAmp(_startFreq,_stopFreq,data.amplifier,data.autorange)
  File "Graph.py", line 938, in addAmp
    _sAMP = form.FloatToString(amp,0)
  File "C:\TMV3\Lib\EngFormat.py", line 8, in FloatToString
    if value >= 1e9:
TypeError: unorderable types: str() >= float()
08.24.2017 10:15:35 unorderable types: str() >= float()
Traceback (most recent call last):
  File "Graph.py", line 1207, in onNewTrace
    self.addAmp(_startFreq,_stopFreq,data.amplifier,data.autorange)
  File "Graph.py", line 938, in addAmp
    _sAMP = form.FloatToString(amp,0)
  File "C:\TMV3\Lib\EngFormat.py", line 8, in FloatToString
    if value >= 1e9:
TypeError: unorderable types: str() >= float()
08.24.2017 10:21:08 TMV3 Measurement started Meas
08.24.2017 10:21:10 [Errno 2] No such file or directory: 'C:\\TMV3\\WorkingDir\\DD_FSWT.py' Meas
Traceback (most recent call last):
  File "C:\TMV3\Routines\RT_StandardHF.py", line 126, in loadDriver
    _py_mod = _loader.load_module()
  File "<frozen importlib._bootstrap>", line 539, in _check_name_wrapper
  File "<frozen importlib._bootstrap>", line 1614, in load_module
  File "<frozen importlib._bootstrap>", line 596, in _load_module_shim
  File "<frozen importlib._bootstrap>", line 1220, in load
  File "<frozen importlib._bootstrap>", line 1200, in _load_unlocked
  File "<frozen importlib._bootstrap>", line 1129, in _exec
  File "<frozen importlib._bootstrap>", line 1467, in exec_module
  File "<frozen importlib._bootstrap>", line 1571, in get_code
  File "<frozen importlib._bootstrap>", line 1623, in get_data
FileNotFoundError: [Errno 2] No such file or directory: 'C:\\TMV3\\WorkingDir\\DD_FSWT.py'
08.24.2017 10:21:40 unorderable types: str() >= float()
Traceback (most recent call last):
  File "Graph.py", line 1208, in onNewTrace
    self.addAmp(_startFreq,_stopFreq,data.amplifier,data.autorange)
  File "Graph.py", line 939, in addAmp
    _sAMP = form.FloatToString(amp,0)
  File "C:\TMV3\Lib\EngFormat.py", line 8, in FloatToString
    if value >= 1e9:
TypeError: unorderable types: str() >= float()
08.24.2017 10:21:54 unorderable types: str() >= float()
Traceback (most recent call last):
  File "Graph.py", line 1208, in onNewTrace
    self.addAmp(_startFreq,_stopFreq,data.amplifier,data.autorange)
  File "Graph.py", line 939, in addAmp
    _sAMP = form.FloatToString(amp,0)
  File "C:\TMV3\Lib\EngFormat.py", line 8, in FloatToString
    if value >= 1e9:
TypeError: unorderable types: str() >= float()
08.24.2017 10:22:08 unorderable types: str() >= float()
Traceback (most recent call last):
  File "Graph.py", line 1208, in onNewTrace
    self.addAmp(_startFreq,_stopFreq,data.amplifier,data.autorange)
  File "Graph.py", line 939, in addAmp
    _sAMP = form.FloatToString(amp,0)
  File "C:\TMV3\Lib\EngFormat.py", line 8, in FloatToString
    if value >= 1e9:
TypeError: unorderable types: str() >= float()
08.24.2017 10:57:07 TMV3 Measurement started Meas
08.24.2017 10:57:09 [Errno 2] No such file or directory: 'C:\\TMV3\\WorkingDir\\DD_FSWT.py' Meas
Traceback (most recent call last):
  File "C:\TMV3\Routines\RT_StandardHF.py", line 126, in loadDriver
    _py_mod = _loader.load_module()
  File "<frozen importlib._bootstrap>", line 539, in _check_name_wrapper
  File "<frozen importlib._bootstrap>", line 1614, in load_module
  File "<frozen importlib._bootstrap>", line 596, in _load_module_shim
  File "<frozen importlib._bootstrap>", line 1220, in load
  File "<frozen importlib._bootstrap>", line 1200, in _load_unlocked
  File "<frozen importlib._bootstrap>", line 1129, in _exec
  File "<frozen importlib._bootstrap>", line 1467, in exec_module
  File "<frozen importlib._bootstrap>", line 1571, in get_code
  File "<frozen importlib._bootstrap>", line 1623, in get_data
FileNotFoundError: [Errno 2] No such file or directory: 'C:\\TMV3\\WorkingDir\\DD_FSWT.py'
08.24.2017 10:57:15 database is locked Server
Traceback (most recent call last):
  File "C:\TMV3\Lib\DB_Handler_TPL3.py", line 1222, in add
    _con.commit()
sqlite3.OperationalError: database is locked
08.24.2017 10:57:20 database is locked Server
Traceback (most recent call last):
  File "C:\TMV3\Lib\DB_Handler_TPL3.py", line 970, in update
    _con.commit()
sqlite3.OperationalError: database is locked
08.24.2017 10:57:25 database is locked Server
Traceback (most recent call last):
  File "C:\TMV3\Lib\DB_Handler_TPL3.py", line 1259, in updateLines
    _con.commit()
sqlite3.OperationalError: database is locked
08.24.2017 10:57:30 database is locked Server
Traceback (most recent call last):
  File "C:\TMV3\Lib\DB_Handler_TPL3.py", line 970, in update
    _con.commit()
sqlite3.OperationalError: database is locked
08.24.2017 10:57:35 database is locked Server
Traceback (most recent call last):
  File "C:\TMV3\Lib\DB_Handler_TPL3.py", line 1259, in updateLines
    _con.commit()
sqlite3.OperationalError: database is locked
08.24.2017 10:57:41 database is locked Server
Traceback (most recent call last):
  File "C:\TMV3\Lib\DB_Handler_TPL3.py", line 970, in update
    _con.commit()
sqlite3.OperationalError: database is locked
08.24.2017 10:57:46 database is locked Server
Traceback (most recent call last):
  File "C:\TMV3\Lib\DB_Handler_TPL3.py", line 1259, in updateLines
    _con.commit()
sqlite3.OperationalError: database is locked
08.24.2017 10:57:51 database is locked Server
Traceback (most recent call last):
  File "C:\TMV3\Lib\DB_Handler_TPL3.py", line 970, in update
    _con.commit()
sqlite3.OperationalError: database is locked
08.24.2017 10:57:56 database is locked Server
Traceback (most recent call last):
  File "C:\TMV3\Lib\DB_Handler_TPL3.py", line 1259, in updateLines
    _con.commit()
sqlite3.OperationalError: database is locked
08.24.2017 10:58:01 database is locked Server
Traceback (most recent call last):
  File "C:\TMV3\Lib\DB_Handler_TPL3.py", line 970, in update
    _con.commit()
sqlite3.OperationalError: database is locked
08.24.2017 10:58:06 database is locked Server
Traceback (most recent call last):
  File "C:\TMV3\Lib\DB_Handler_TPL3.py", line 1259, in updateLines
    _con.commit()
sqlite3.OperationalError: database is locked
08.24.2017 10:58:11 database is locked Server
Traceback (most recent call last):
  File "C:\TMV3\Lib\DB_Handler_TPL3.py", line 1073, in add
    _con.commit()
sqlite3.OperationalError: database is locked
08.24.2017 10:58:16 database is locked Server
Traceback (most recent call last):
  File "C:\TMV3\Lib\DB_Handler_TPL3.py", line 1293, in updateRoutine
    _con.commit()
sqlite3.OperationalError: database is locked
08.24.2017 10:58:21 database is locked Server
Traceback (most recent call last):
  File "C:\TMV3\Lib\DB_Handler_TPL3.py", line 970, in update
    _con.commit()
sqlite3.OperationalError: database is locked
08.24.2017 10:58:26 database is locked Server
Traceback (most recent call last):
  File "C:\TMV3\Lib\DB_Handler_TPL3.py", line 1259, in updateLines
    _con.commit()
sqlite3.OperationalError: database is locked
08.24.2017 10:58:31 database is locked Server
Traceback (most recent call last):
  File "C:\TMV3\Lib\DB_Handler_TPL3.py", line 970, in update
    _con.commit()
sqlite3.OperationalError: database is locked
08.24.2017 10:58:36 database is locked Server
Traceback (most recent call last):
  File "C:\TMV3\Lib\DB_Handler_TPL3.py", line 1259, in updateLines
    _con.commit()
sqlite3.OperationalError: database is locked
08.24.2017 11:03:18 recv 1fd1128 error WSAECONNRESET Server
08.24.2017 11:03:57 TMV3 Measurement started Meas
08.24.2017 11:03:59 [Errno 2] No such file or directory: 'C:\\TMV3\\WorkingDir\\DD_FSWT.py' Meas
Traceback (most recent call last):
  File "C:\TMV3\Routines\RT_StandardHF.py", line 126, in loadDriver
    _py_mod = _loader.load_module()
  File "<frozen importlib._bootstrap>", line 539, in _check_name_wrapper
  File "<frozen importlib._bootstrap>", line 1614, in load_module
  File "<frozen importlib._bootstrap>", line 596, in _load_module_shim
  File "<frozen importlib._bootstrap>", line 1220, in load
  File "<frozen importlib._bootstrap>", line 1200, in _load_unlocked
  File "<frozen importlib._bootstrap>", line 1129, in _exec
  File "<frozen importlib._bootstrap>", line 1467, in exec_module
  File "<frozen importlib._bootstrap>", line 1571, in get_code
  File "<frozen importlib._bootstrap>", line 1623, in get_data
FileNotFoundError: [Errno 2] No such file or directory: 'C:\\TMV3\\WorkingDir\\DD_FSWT.py'
08.24.2017 11:04:05 database is locked Server
Traceback (most recent call last):
  File "C:\TMV3\Lib\DB_Handler_TPL3.py", line 1222, in add
    _con.commit()
sqlite3.OperationalError: database is locked
08.24.2017 11:04:10 database is locked Server
Traceback (most recent call last):
  File "C:\TMV3\Lib\DB_Handler_TPL3.py", line 970, in update
    _con.commit()
sqlite3.OperationalError: database is locked
08.24.2017 11:04:15 database is locked Server
Traceback (most recent call last):
  File "C:\TMV3\Lib\DB_Handler_TPL3.py", line 1259, in updateLines
    _con.commit()
sqlite3.OperationalError: database is locked
08.24.2017 11:04:20 database is locked Server
Traceback (most recent call last):
  File "C:\TMV3\Lib\DB_Handler_TPL3.py", line 970, in update
    _con.commit()
sqlite3.OperationalError: database is locked
08.24.2017 11:04:25 database is locked Server
Traceback (most recent call last):
  File "C:\TMV3\Lib\DB_Handler_TPL3.py", line 1259, in updateLines
    _con.commit()
sqlite3.OperationalError: database is locked
08.24.2017 11:04:30 database is locked Server
Traceback (most recent call last):
  File "C:\TMV3\Lib\DB_Handler_TPL3.py", line 970, in update
    _con.commit()
sqlite3.OperationalError: database is locked
08.24.2017 11:04:35 database is locked Server
Traceback (most recent call last):
  File "C:\TMV3\Lib\DB_Handler_TPL3.py", line 1259, in updateLines
    _con.commit()
sqlite3.OperationalError: database is locked
08.24.2017 11:04:40 database is locked Server
Traceback (most recent call last):
  File "C:\TMV3\Lib\DB_Handler_TPL3.py", line 970, in update
    _con.commit()
sqlite3.OperationalError: database is locked
08.24.2017 11:04:46 database is locked Server
Traceback (most recent call last):
  File "C:\TMV3\Lib\DB_Handler_TPL3.py", line 1259, in updateLines
    _con.commit()
sqlite3.OperationalError: database is locked
08.24.2017 11:04:51 database is locked Server
Traceback (most recent call last):
  File "C:\TMV3\Lib\DB_Handler_TPL3.py", line 970, in update
    _con.commit()
sqlite3.OperationalError: database is locked
08.24.2017 11:04:56 database is locked Server
Traceback (most recent call last):
  File "C:\TMV3\Lib\DB_Handler_TPL3.py", line 1259, in updateLines
    _con.commit()
sqlite3.OperationalError: database is locked
08.24.2017 11:05:01 database is locked Server
Traceback (most recent call last):
  File "C:\TMV3\Lib\DB_Handler_TPL3.py", line 1073, in add
    _con.commit()
sqlite3.OperationalError: database is locked
08.24.2017 11:05:06 database is locked Server
Traceback (most recent call last):
  File "C:\TMV3\Lib\DB_Handler_TPL3.py", line 1293, in updateRoutine
    _con.commit()
sqlite3.OperationalError: database is locked
08.24.2017 11:05:11 database is locked Server
Traceback (most recent call last):
  File "C:\TMV3\Lib\DB_Handler_TPL3.py", line 970, in update
    _con.commit()
sqlite3.OperationalError: database is locked
08.24.2017 11:05:16 database is locked Server
Traceback (most recent call last):
  File "C:\TMV3\Lib\DB_Handler_TPL3.py", line 1259, in updateLines
    _con.commit()
sqlite3.OperationalError: database is locked
08.24.2017 11:05:21 database is locked Server
Traceback (most recent call last):
  File "C:\TMV3\Lib\DB_Handler_TPL3.py", line 970, in update
    _con.commit()
sqlite3.OperationalError: database is locked
08.24.2017 11:05:26 database is locked Server
Traceback (most recent call last):
  File "C:\TMV3\Lib\DB_Handler_TPL3.py", line 1259, in updateLines
    _con.commit()
sqlite3.OperationalError: database is locked
08.24.2017 11:09:19 recv 1fd1584 error WSAECONNRESET Server
08.24.2017 11:09:19 TMV3 Measurement started Meas
08.24.2017 11:09:20 [Errno 2] No such file or directory: 'C:\\TMV3\\WorkingDir\\DD_FSWT.py' Meas
Traceback (most recent call last):
  File "C:\TMV3\Routines\RT_StandardHF.py", line 126, in loadDriver
    _py_mod = _loader.load_module()
  File "<frozen importlib._bootstrap>", line 539, in _check_name_wrapper
  File "<frozen importlib._bootstrap>", line 1614, in load_module
  File "<frozen importlib._bootstrap>", line 596, in _load_module_shim
  File "<frozen importlib._bootstrap>", line 1220, in load
  File "<frozen importlib._bootstrap>", line 1200, in _load_unlocked
  File "<frozen importlib._bootstrap>", line 1129, in _exec
  File "<frozen importlib._bootstrap>", line 1467, in exec_module
  File "<frozen importlib._bootstrap>", line 1571, in get_code
  File "<frozen importlib._bootstrap>", line 1623, in get_data
FileNotFoundError: [Errno 2] No such file or directory: 'C:\\TMV3\\WorkingDir\\DD_FSWT.py'
08.24.2017 11:17:37 TMV3 Measurement started Meas
08.24.2017 11:17:39 [Errno 2] No such file or directory: 'C:\\TMV3\\WorkingDir\\DD_FSWT.py' Meas
Traceback (most recent call last):
  File "C:\TMV3\Routines\RT_StandardHF.py", line 126, in loadDriver
    _py_mod = _loader.load_module()
  File "<frozen importlib._bootstrap>", line 539, in _check_name_wrapper
  File "<frozen importlib._bootstrap>", line 1614, in load_module
  File "<frozen importlib._bootstrap>", line 596, in _load_module_shim
  File "<frozen importlib._bootstrap>", line 1220, in load
  File "<frozen importlib._bootstrap>", line 1200, in _load_unlocked
  File "<frozen importlib._bootstrap>", line 1129, in _exec
  File "<frozen importlib._bootstrap>", line 1467, in exec_module
  File "<frozen importlib._bootstrap>", line 1571, in get_code
  File "<frozen importlib._bootstrap>", line 1623, in get_data
FileNotFoundError: [Errno 2] No such file or directory: 'C:\\TMV3\\WorkingDir\\DD_FSWT.py'
08.24.2017 12:20:45 recv 1fd1600 error WSAECONNRESET Server
08.29.2017 10:27:36 TMV3 Measurement started Meas
08.29.2017 10:27:38 [Errno 2] No such file or directory: 'C:\\TMV3\\WorkingDir\\DD_FSWT.py' Meas
Traceback (most recent call last):
  File "C:\TMV3\Routines\RT_StandardHF.py", line 126, in loadDriver
    _py_mod = _loader.load_module()
  File "<frozen importlib._bootstrap>", line 539, in _check_name_wrapper
  File "<frozen importlib._bootstrap>", line 1614, in load_module
  File "<frozen importlib._bootstrap>", line 596, in _load_module_shim
  File "<frozen importlib._bootstrap>", line 1220, in load
  File "<frozen importlib._bootstrap>", line 1200, in _load_unlocked
  File "<frozen importlib._bootstrap>", line 1129, in _exec
  File "<frozen importlib._bootstrap>", line 1467, in exec_module
  File "<frozen importlib._bootstrap>", line 1571, in get_code
  File "<frozen importlib._bootstrap>", line 1623, in get_data
FileNotFoundError: [Errno 2] No such file or directory: 'C:\\TMV3\\WorkingDir\\DD_FSWT.py'
08.29.2017 10:27:44 VI_ERROR_NLISTENERS (-1073807265): No listeners condition is detected (both NRFD and NDAC are deasserted). Meas
Traceback (most recent call last):
  File "C:\TMV3\DeviceDriver\DD_Analyzer.py", line 54, in checkConnection
    _ret = self.sa.query("*IDN?")
  File "C:\Python34\lib\site-packages\pyvisa\resources\messagebased.py", line 401, in query
    self.write(message)
  File "C:\Python34\lib\site-packages\pyvisa\resources\messagebased.py", line 207, in write
    count = self.write_raw(message.encode(enco))
  File "C:\Python34\lib\site-packages\pyvisa\resources\messagebased.py", line 185, in write_raw
    return self.visalib.write(self.session, message)
  File "C:\Python34\lib\site-packages\pyvisa\ctwrapper\functions.py", line 1864, in write
    ret = library.viWrite(session, data, len(data), byref(return_count))
  File "C:\Python34\lib\site-packages\pyvisa\ctwrapper\highlevel.py", line 188, in _return_handler
    raise errors.VisaIOError(ret_value)
pyvisa.errors.VisaIOError: VI_ERROR_NLISTENERS (-1073807265): No listeners condition is detected (both NRFD and NDAC are deasserted).
08.29.2017 10:30:24 recv 2fd1640 error WSAECONNRESET Server
08.29.2017 10:30:25 recv 1fd1132 error WSAECONNRESET Server
08.29.2017 10:30:25 TMV3 Measurement started Meas
08.29.2017 10:30:27 [Errno 2] No such file or directory: 'C:\\TMV3\\WorkingDir\\DD_FSWT.py' Meas
Traceback (most recent call last):
  File "C:\TMV3\Routines\RT_StandardHF.py", line 126, in loadDriver
    _py_mod = _loader.load_module()
  File "<frozen importlib._bootstrap>", line 539, in _check_name_wrapper
  File "<frozen importlib._bootstrap>", line 1614, in load_module
  File "<frozen importlib._bootstrap>", line 596, in _load_module_shim
  File "<frozen importlib._bootstrap>", line 1220, in load
  File "<frozen importlib._bootstrap>", line 1200, in _load_unlocked
  File "<frozen importlib._bootstrap>", line 1129, in _exec
  File "<frozen importlib._bootstrap>", line 1467, in exec_module
  File "<frozen importlib._bootstrap>", line 1571, in get_code
  File "<frozen importlib._bootstrap>", line 1623, in get_data
FileNotFoundError: [Errno 2] No such file or directory: 'C:\\TMV3\\WorkingDir\\DD_FSWT.py'
08.29.2017 10:51:02 recv 4fd1664 error WSAECONNRESET Server
08.29.2017 10:51:03 recv 3fd1608 error WSAECONNRESET Server
08.29.2017 10:51:04 TMV3 Measurement started Meas
08.29.2017 10:51:05 [Errno 2] No such file or directory: 'C:\\TMV3\\WorkingDir\\DD_FSWT.py' Meas
Traceback (most recent call last):
  File "C:\TMV3\Routines\RT_StandardHF.py", line 126, in loadDriver
    _py_mod = _loader.load_module()
  File "<frozen importlib._bootstrap>", line 539, in _check_name_wrapper
  File "<frozen importlib._bootstrap>", line 1614, in load_module
  File "<frozen importlib._bootstrap>", line 596, in _load_module_shim
  File "<frozen importlib._bootstrap>", line 1220, in load
  File "<frozen importlib._bootstrap>", line 1200, in _load_unlocked
  File "<frozen importlib._bootstrap>", line 1129, in _exec
  File "<frozen importlib._bootstrap>", line 1467, in exec_module
  File "<frozen importlib._bootstrap>", line 1571, in get_code
  File "<frozen importlib._bootstrap>", line 1623, in get_data
FileNotFoundError: [Errno 2] No such file or directory: 'C:\\TMV3\\WorkingDir\\DD_FSWT.py'
08.29.2017 10:51:53 recv 6fd1104 error WSAECONNRESET Server
08.29.2017 10:53:20 TMV3 Measurement started Meas
08.29.2017 10:53:28 [Errno 2] No such file or directory: 'C:\\TMV3\\WorkingDir\\DD_FSWT.py' Meas
Traceback (most recent call last):
  File "C:\TMV3\Routines\RT_StandardHF.py", line 126, in loadDriver
    _py_mod = _loader.load_module()
  File "<frozen importlib._bootstrap>", line 539, in _check_name_wrapper
  File "<frozen importlib._bootstrap>", line 1614, in load_module
  File "<frozen importlib._bootstrap>", line 596, in _load_module_shim
  File "<frozen importlib._bootstrap>", line 1220, in load
  File "<frozen importlib._bootstrap>", line 1200, in _load_unlocked
  File "<frozen importlib._bootstrap>", line 1129, in _exec
  File "<frozen importlib._bootstrap>", line 1467, in exec_module
  File "<frozen importlib._bootstrap>", line 1571, in get_code
  File "<frozen importlib._bootstrap>", line 1623, in get_data
FileNotFoundError: [Errno 2] No such file or directory: 'C:\\TMV3\\WorkingDir\\DD_FSWT.py'
08.29.2017 11:00:39 recv 2fd1904 error WSAECONNRESET Server
08.29.2017 11:00:40 recv 1fd1268 error WSAECONNRESET Server
08.29.2017 11:00:42 TMV3 Measurement started Meas
08.29.2017 11:00:44 [Errno 2] No such file or directory: 'C:\\TMV3\\WorkingDir\\DD_FSWT.py' Meas
Traceback (most recent call last):
  File "C:\TMV3\Routines\RT_StandardHF.py", line 126, in loadDriver
    _py_mod = _loader.load_module()
  File "<frozen importlib._bootstrap>", line 539, in _check_name_wrapper
  File "<frozen importlib._bootstrap>", line 1614, in load_module
  File "<frozen importlib._bootstrap>", line 596, in _load_module_shim
  File "<frozen importlib._bootstrap>", line 1220, in load
  File "<frozen importlib._bootstrap>", line 1200, in _load_unlocked
  File "<frozen importlib._bootstrap>", line 1129, in _exec
  File "<frozen importlib._bootstrap>", line 1467, in exec_module
  File "<frozen importlib._bootstrap>", line 1571, in get_code
  File "<frozen importlib._bootstrap>", line 1623, in get_data
FileNotFoundError: [Errno 2] No such file or directory: 'C:\\TMV3\\WorkingDir\\DD_FSWT.py'
08.29.2017 11:00:44 unindent does not match any outer indentation level (DD_FSET.py, line 142) Meas
Traceback (most recent call last):
  File "C:\TMV3\Routines\RT_StandardHF.py", line 126, in loadDriver
    _py_mod = _loader.load_module()
  File "<frozen importlib._bootstrap>", line 539, in _check_name_wrapper
  File "<frozen importlib._bootstrap>", line 1614, in load_module
  File "<frozen importlib._bootstrap>", line 596, in _load_module_shim
  File "<frozen importlib._bootstrap>", line 1220, in load
  File "<frozen importlib._bootstrap>", line 1200, in _load_unlocked
  File "<frozen importlib._bootstrap>", line 1129, in _exec
  File "<frozen importlib._bootstrap>", line 1467, in exec_module
  File "<frozen importlib._bootstrap>", line 1572, in get_code
  File "<frozen importlib._bootstrap>", line 1532, in source_to_code
  File "<frozen importlib._bootstrap>", line 321, in _call_with_frames_removed
  File "C:\TMV3\WorkingDir\DD_FSET.py", line 142
    else:
        ^
IndentationError: unindent does not match any outer indentation level
08.29.2017 11:01:02 recv 4fd1124 error WSAECONNRESET Server
08.29.2017 11:01:51 TMV3 Measurement started Meas
08.29.2017 11:01:53 [Errno 2] No such file or directory: 'C:\\TMV3\\WorkingDir\\DD_FSWT.py' Meas
Traceback (most recent call last):
  File "C:\TMV3\Routines\RT_StandardHF.py", line 126, in loadDriver
    _py_mod = _loader.load_module()
  File "<frozen importlib._bootstrap>", line 539, in _check_name_wrapper
  File "<frozen importlib._bootstrap>", line 1614, in load_module
  File "<frozen importlib._bootstrap>", line 596, in _load_module_shim
  File "<frozen importlib._bootstrap>", line 1220, in load
  File "<frozen importlib._bootstrap>", line 1200, in _load_unlocked
  File "<frozen importlib._bootstrap>", line 1129, in _exec
  File "<frozen importlib._bootstrap>", line 1467, in exec_module
  File "<frozen importlib._bootstrap>", line 1571, in get_code
  File "<frozen importlib._bootstrap>", line 1623, in get_data
FileNotFoundError: [Errno 2] No such file or directory: 'C:\\TMV3\\WorkingDir\\DD_FSWT.py'
08.29.2017 11:01:57 math domain error Meas
Traceback (most recent call last):
  File "C:\TMV3\Routines\RT_StandardHF.py", line 437, in startTrace
    _ret, amp, att =  _func()
  File "C:\TMV3\WorkingDir\DD_FSET.py", line 135, in autoRange
    NoiseSignal = _ATT + 10 * math.log10(self.ResBw / 1000) - 7.3 + 10
ValueError: math domain error
08.29.2017 11:02:55 TMV3 Measurement started Meas
08.29.2017 11:02:56 [Errno 2] No such file or directory: 'C:\\TMV3\\WorkingDir\\DD_FSWT.py' Meas
Traceback (most recent call last):
  File "C:\TMV3\Routines\RT_StandardHF.py", line 126, in loadDriver
    _py_mod = _loader.load_module()
  File "<frozen importlib._bootstrap>", line 539, in _check_name_wrapper
  File "<frozen importlib._bootstrap>", line 1614, in load_module
  File "<frozen importlib._bootstrap>", line 596, in _load_module_shim
  File "<frozen importlib._bootstrap>", line 1220, in load
  File "<frozen importlib._bootstrap>", line 1200, in _load_unlocked
  File "<frozen importlib._bootstrap>", line 1129, in _exec
  File "<frozen importlib._bootstrap>", line 1467, in exec_module
  File "<frozen importlib._bootstrap>", line 1571, in get_code
  File "<frozen importlib._bootstrap>", line 1623, in get_data
FileNotFoundError: [Errno 2] No such file or directory: 'C:\\TMV3\\WorkingDir\\DD_FSWT.py'
08.29.2017 11:05:59 TMV3 Measurement started Meas
08.29.2017 11:06:00 [Errno 2] No such file or directory: 'C:\\TMV3\\WorkingDir\\DD_FSWT.py' Meas
Traceback (most recent call last):
  File "C:\TMV3\Routines\RT_StandardHF.py", line 126, in loadDriver
    _py_mod = _loader.load_module()
  File "<frozen importlib._bootstrap>", line 539, in _check_name_wrapper
  File "<frozen importlib._bootstrap>", line 1614, in load_module
  File "<frozen importlib._bootstrap>", line 596, in _load_module_shim
  File "<frozen importlib._bootstrap>", line 1220, in load
  File "<frozen importlib._bootstrap>", line 1200, in _load_unlocked
  File "<frozen importlib._bootstrap>", line 1129, in _exec
  File "<frozen importlib._bootstrap>", line 1467, in exec_module
  File "<frozen importlib._bootstrap>", line 1571, in get_code
  File "<frozen importlib._bootstrap>", line 1623, in get_data
FileNotFoundError: [Errno 2] No such file or directory: 'C:\\TMV3\\WorkingDir\\DD_FSWT.py'
09.04.2017 10:36:29 TMV3 Measurement started Meas
09.04.2017 10:36:29 [Errno 2] No such file or directory: 'C:\\TMV3\\WorkingDir\\DD_FSWT.py' Meas
Traceback (most recent call last):
  File "C:\TMV3\Routines\RT_StandardHF.py", line 126, in loadDriver
    _py_mod = _loader.load_module()
  File "<frozen importlib._bootstrap>", line 539, in _check_name_wrapper
  File "<frozen importlib._bootstrap>", line 1614, in load_module
  File "<frozen importlib._bootstrap>", line 596, in _load_module_shim
  File "<frozen importlib._bootstrap>", line 1220, in load
  File "<frozen importlib._bootstrap>", line 1200, in _load_unlocked
  File "<frozen importlib._bootstrap>", line 1129, in _exec
  File "<frozen importlib._bootstrap>", line 1467, in exec_module
  File "<frozen importlib._bootstrap>", line 1571, in get_code
  File "<frozen importlib._bootstrap>", line 1623, in get_data
FileNotFoundError: [Errno 2] No such file or directory: 'C:\\TMV3\\WorkingDir\\DD_FSWT.py'
09.04.2017 10:36:30 VI_ERROR_BERR (-1073807304): Bus error occurred during transfer. Meas
Traceback (most recent call last):
  File "C:\TMV3\DeviceDriver\DD_Analyzer.py", line 52, in checkConnection
    self.sa = self.rm.open_resource(self.name)
  File "C:\Python34\lib\site-packages\pyvisa\highlevel.py", line 1644, in open_resource
    res.open(access_mode, open_timeout)
  File "C:\Python34\lib\site-packages\pyvisa\resources\resource.py", line 215, in open
    self.clear()
  File "C:\Python34\lib\site-packages\pyvisa\resources\resource.py", line 270, in clear
    self.visalib.clear(self.session)
  File "C:\Python34\lib\site-packages\pyvisa\ctwrapper\functions.py", line 379, in clear
    return library.viClear(session)
  File "C:\Python34\lib\site-packages\pyvisa\ctwrapper\highlevel.py", line 188, in _return_handler
    raise errors.VisaIOError(ret_value)
pyvisa.errors.VisaIOError: VI_ERROR_BERR (-1073807304): Bus error occurred during transfer.
09.04.2017 10:36:55 recv 1fd1132 error WSAECONNRESET Server
09.04.2017 10:38:03 TMV3 Measurement started Meas
09.04.2017 10:38:04 -178,"Expression data not allowed;SENSE:FREQ:START ('10000.0'"
 Meas
09.04.2017 10:48:47 TMV3 Measurement started Meas
09.04.2017 10:48:48 -178,"Expression data not allowed;SENSE:FREQ:START ('10000.0'"
 Meas
09.04.2017 10:50:30 recv 1fd1104 error WSAECONNRESET Server
09.04.2017 10:50:48 TMV3 Measurement started Meas
09.04.2017 10:50:49 -178,"Expression data not allowed;SENSE:FREQ:START ('10000.0'"
 Meas
09.04.2017 10:55:15 TMV3 Measurement started Meas
09.04.2017 10:55:15 -178,"Expression data not allowed;SENSE:FREQ:START ('10000.0'"
 Meas
09.04.2017 10:56:22 TMV3 Measurement started Meas
09.04.2017 10:56:23 -178,"Expression data not allowed;SENSE:FREQ:START ('10000.0'"
 Meas
09.04.2017 10:58:12 TMV3 Measurement started Meas
09.04.2017 10:58:13 -178,"Expression data not allowed;SENSE:FREQ:START ('10000.0'"
 Meas
09.04.2017 10:59:24 TMV3 Measurement started Meas
09.04.2017 10:59:25 -178,"Expression data not allowed;SENSE:FREQ:START ('10000.0'"
 Meas
09.04.2017 01:26:45 recv 2fd1616 error WSAECONNRESET Server
09.04.2017 02:20:51 TMV3 Measurement started Meas
09.04.2017 02:20:52 VI_ERROR_RSRC_NFOUND (-1073807343): Insufficient location information or the requested device or resource is not present in the system. Meas
Traceback (most recent call last):
  File "C:\TMV3\DeviceDriver\DD_Analyzer.py", line 52, in checkConnection
    self.sa = self.rm.open_resource(self.name)
  File "C:\Python34\lib\site-packages\pyvisa\highlevel.py", line 1623, in open_resource
    info = self.resource_info(resource_name, extended=True)
  File "C:\Python34\lib\site-packages\pyvisa\highlevel.py", line 1583, in resource_info
    ret, err = self.visalib.parse_resource_extended(self.session, resource_name)
  File "C:\Python34\lib\site-packages\pyvisa\ctwrapper\functions.py", line 1381, in parse_resource_extended
    alias_if_exists)
  File "C:\Python34\lib\site-packages\pyvisa\ctwrapper\highlevel.py", line 188, in _return_handler
    raise errors.VisaIOError(ret_value)
pyvisa.errors.VisaIOError: VI_ERROR_RSRC_NFOUND (-1073807343): Insufficient location information or the requested device or resource is not present in the system.
09.04.2017 02:20:52 VI_ERROR_BERR (-1073807304): Bus error occurred during transfer. Meas
Traceback (most recent call last):
  File "C:\TMV3\DeviceDriver\DD_Analyzer.py", line 52, in checkConnection
    self.sa = self.rm.open_resource(self.name)
  File "C:\Python34\lib\site-packages\pyvisa\highlevel.py", line 1644, in open_resource
    res.open(access_mode, open_timeout)
  File "C:\Python34\lib\site-packages\pyvisa\resources\resource.py", line 215, in open
    self.clear()
  File "C:\Python34\lib\site-packages\pyvisa\resources\resource.py", line 270, in clear
    self.visalib.clear(self.session)
  File "C:\Python34\lib\site-packages\pyvisa\ctwrapper\functions.py", line 379, in clear
    return library.viClear(session)
  File "C:\Python34\lib\site-packages\pyvisa\ctwrapper\highlevel.py", line 188, in _return_handler
    raise errors.VisaIOError(ret_value)
pyvisa.errors.VisaIOError: VI_ERROR_BERR (-1073807304): Bus error occurred during transfer.
09.04.2017 02:22:28 TMV3 Measurement started Meas
09.04.2017 02:22:29 -178,"Expression data not allowed;SENSE:FREQ:START ('10000.0'"
 Meas
09.04.2017 02:23:09 TMV3 Measurement started Meas
09.04.2017 02:23:10 -178,"Expression data not allowed;SENSE:FREQ:START ('10000.0'"
 Meas
09.04.2017 02:25:00 TMV3 Measurement started Meas
09.04.2017 02:25:01 float() takes at most 1 argument (7 given) Meas
Traceback (most recent call last):
  File "C:\TMV3\Routines\RT_StandardHF.py", line 316, in startSetting
    _ret = _func(row.parameter)
  File "C:\TMV3\WorkingDir\DD_FSWT.py", line 42, in set_StopFreq
    f = float(*par[0])
TypeError: float() takes at most 1 argument (7 given)
09.04.2017 02:26:32 TMV3 Measurement started Meas
09.04.2017 02:26:33 float() takes at most 1 argument (7 given) Meas
Traceback (most recent call last):
  File "C:\TMV3\Routines\RT_StandardHF.py", line 316, in startSetting
    _ret = _func(row.parameter)
  File "C:\TMV3\WorkingDir\DD_FSWT.py", line 39, in set_StopFreq
    f = float(*par[0])
TypeError: float() takes at most 1 argument (7 given)
09.04.2017 02:27:30 TMV3 Measurement started Meas
09.04.2017 02:27:31 -222,"Data out of range;SENSE:FREQ:STOP 2HZ"
 Meas
09.04.2017 02:30:01 TMV3 Measurement started Meas
09.04.2017 02:30:02 -178,"Expression data not allowed;SENSE:BAND ('5000.0',)"
 Meas
09.04.2017 02:30:07 recv 2fd1632 error WSAECONNRESET Server
09.04.2017 02:32:30 TMV3 Measurement started Meas
09.04.2017 02:32:31 float() argument must be a string or a number, not 'tuple' Meas
Traceback (most recent call last):
  File "C:\TMV3\Routines\RT_StandardHF.py", line 316, in startSetting
    _ret = _func(row.parameter)
  File "C:\TMV3\WorkingDir\DD_FSWT.py", line 123, in set_VidBW
    if float(par) > 50e6:
TypeError: float() argument must be a string or a number, not 'tuple'
09.04.2017 02:33:55 TMV3 Measurement started Meas
09.04.2017 02:33:56 float() argument must be a string or a number, not 'tuple' Meas
Traceback (most recent call last):
  File "C:\TMV3\Routines\RT_StandardHF.py", line 316, in startSetting
    _ret = _func(row.parameter)
  File "C:\TMV3\WorkingDir\DD_FSWT.py", line 122, in set_VidBW
    if float(par) > 50e6:
TypeError: float() argument must be a string or a number, not 'tuple'
09.04.2017 02:35:13 TMV3 Measurement started Meas
09.04.2017 02:35:14 float() argument must be a string or a number, not 'tuple' Meas
Traceback (most recent call last):
  File "C:\TMV3\Routines\RT_StandardHF.py", line 316, in startSetting
    _ret = _func(row.parameter)
  File "C:\TMV3\WorkingDir\DD_FSWT.py", line 122, in set_VidBW
    if float(par) > 50e6:
TypeError: float() argument must be a string or a number, not 'tuple'
09.04.2017 02:37:11 TMV3 Measurement started Meas
09.04.2017 02:37:12 -141,"Invalid character data;INP:PRES:SET N"
 Meas
09.04.2017 02:42:02 TMV3 Measurement started Meas
09.04.2017 02:42:03 -141,"Invalid character data;INP:PRES:SET N"
 Meas
09.04.2017 02:43:53 TMV3 Measurement started Meas
09.04.2017 02:43:55 VI_ERROR_BERR (-1073807304): Bus error occurred during transfer. Meas
Traceback (most recent call last):
  File "C:\TMV3\DeviceDriver\DD_Relais.py", line 34, in checkConnection
    self.rl = self.rm.open_resource(self.name)
  File "C:\Python34\lib\site-packages\pyvisa\highlevel.py", line 1644, in open_resource
    res.open(access_mode, open_timeout)
  File "C:\Python34\lib\site-packages\pyvisa\resources\resource.py", line 215, in open
    self.clear()
  File "C:\Python34\lib\site-packages\pyvisa\resources\resource.py", line 270, in clear
    self.visalib.clear(self.session)
  File "C:\Python34\lib\site-packages\pyvisa\ctwrapper\functions.py", line 379, in clear
    return library.viClear(session)
  File "C:\Python34\lib\site-packages\pyvisa\ctwrapper\highlevel.py", line 188, in _return_handler
    raise errors.VisaIOError(ret_value)
pyvisa.errors.VisaIOError: VI_ERROR_BERR (-1073807304): Bus error occurred during transfer.
09.04.2017 02:44:14 -257,"File name error;CORR:TSET:DEL"
 Meas
09.04.2017 02:44:36 VI_ERROR_BERR (-1073807304): Bus error occurred during transfer. Meas
Traceback (most recent call last):
  File "C:\TMV3\DeviceDriver\DD_Relais.py", line 34, in checkConnection
    self.rl = self.rm.open_resource(self.name)
  File "C:\Python34\lib\site-packages\pyvisa\highlevel.py", line 1644, in open_resource
    res.open(access_mode, open_timeout)
  File "C:\Python34\lib\site-packages\pyvisa\resources\resource.py", line 215, in open
    self.clear()
  File "C:\Python34\lib\site-packages\pyvisa\resources\resource.py", line 270, in clear
    self.visalib.clear(self.session)
  File "C:\Python34\lib\site-packages\pyvisa\ctwrapper\functions.py", line 379, in clear
    return library.viClear(session)
  File "C:\Python34\lib\site-packages\pyvisa\ctwrapper\highlevel.py", line 188, in _return_handler
    raise errors.VisaIOError(ret_value)
pyvisa.errors.VisaIOError: VI_ERROR_BERR (-1073807304): Bus error occurred during transfer.
09.04.2017 02:44:59 VI_ERROR_BERR (-1073807304): Bus error occurred during transfer. Meas
Traceback (most recent call last):
  File "C:\TMV3\DeviceDriver\DD_Relais.py", line 34, in checkConnection
    self.rl = self.rm.open_resource(self.name)
  File "C:\Python34\lib\site-packages\pyvisa\highlevel.py", line 1644, in open_resource
    res.open(access_mode, open_timeout)
  File "C:\Python34\lib\site-packages\pyvisa\resources\resource.py", line 215, in open
    self.clear()
  File "C:\Python34\lib\site-packages\pyvisa\resources\resource.py", line 270, in clear
    self.visalib.clear(self.session)
  File "C:\Python34\lib\site-packages\pyvisa\ctwrapper\functions.py", line 379, in clear
    return library.viClear(session)
  File "C:\Python34\lib\site-packages\pyvisa\ctwrapper\highlevel.py", line 188, in _return_handler
    raise errors.VisaIOError(ret_value)
pyvisa.errors.VisaIOError: VI_ERROR_BERR (-1073807304): Bus error occurred during transfer.
09.04.2017 02:45:36 recv 2fd1636 error WSAECONNRESET Server
09.04.2017 02:45:53 TMV3 Measurement started Meas
09.04.2017 02:48:30 -257,"File name error;CORR:TSET:DEL"
 Meas
09.04.2017 02:49:49 -257,"File name error;CORR:TSET:DEL"
 Meas
09.04.2017 03:05:47 -200,"Execution error;Function not available;SENSE:BAND:VID 100000000.0"
 Meas
09.04.2017 03:09:59 TMV3 Measurement started Meas
09.04.2017 03:10:01 invalid syntax (DD_FSWT.py, line 75) Meas
Traceback (most recent call last):
  File "C:\TMV3\Routines\RT_StandardHF.py", line 126, in loadDriver
    _py_mod = _loader.load_module()
  File "<frozen importlib._bootstrap>", line 539, in _check_name_wrapper
  File "<frozen importlib._bootstrap>", line 1614, in load_module
  File "<frozen importlib._bootstrap>", line 596, in _load_module_shim
  File "<frozen importlib._bootstrap>", line 1220, in load
  File "<frozen importlib._bootstrap>", line 1200, in _load_unlocked
  File "<frozen importlib._bootstrap>", line 1129, in _exec
  File "<frozen importlib._bootstrap>", line 1467, in exec_module
  File "<frozen importlib._bootstrap>", line 1572, in get_code
  File "<frozen importlib._bootstrap>", line 1532, in source_to_code
  File "<frozen importlib._bootstrap>", line 321, in _call_with_frames_removed
  File "C:\TMV3\WorkingDir\DD_FSWT.py", line 75
    def set_StepTime(self,*par:'f0'):
      ^
SyntaxError: invalid syntax
09.04.2017 03:10:07 VI_ERROR_NLISTENERS (-1073807265): No listeners condition is detected (both NRFD and NDAC are deasserted). Meas
Traceback (most recent call last):
  File "C:\TMV3\DeviceDriver\DD_Analyzer.py", line 54, in checkConnection
    _ret = self.sa.query("*IDN?")
  File "C:\Python34\lib\site-packages\pyvisa\resources\messagebased.py", line 401, in query
    self.write(message)
  File "C:\Python34\lib\site-packages\pyvisa\resources\messagebased.py", line 207, in write
    count = self.write_raw(message.encode(enco))
  File "C:\Python34\lib\site-packages\pyvisa\resources\messagebased.py", line 185, in write_raw
    return self.visalib.write(self.session, message)
  File "C:\Python34\lib\site-packages\pyvisa\ctwrapper\functions.py", line 1864, in write
    ret = library.viWrite(session, data, len(data), byref(return_count))
  File "C:\Python34\lib\site-packages\pyvisa\ctwrapper\highlevel.py", line 188, in _return_handler
    raise errors.VisaIOError(ret_value)
pyvisa.errors.VisaIOError: VI_ERROR_NLISTENERS (-1073807265): No listeners condition is detected (both NRFD and NDAC are deasserted).
09.04.2017 03:10:30 recv 2fd1660 error WSAECONNRESET Server
09.04.2017 03:11:09 TMV3 Measurement started Meas
09.04.2017 03:11:11 invalid syntax (DD_FSWT.py, line 75) Meas
Traceback (most recent call last):
  File "C:\TMV3\Routines\RT_StandardHF.py", line 126, in loadDriver
    _py_mod = _loader.load_module()
  File "<frozen importlib._bootstrap>", line 539, in _check_name_wrapper
  File "<frozen importlib._bootstrap>", line 1614, in load_module
  File "<frozen importlib._bootstrap>", line 596, in _load_module_shim
  File "<frozen importlib._bootstrap>", line 1220, in load
  File "<frozen importlib._bootstrap>", line 1200, in _load_unlocked
  File "<frozen importlib._bootstrap>", line 1129, in _exec
  File "<frozen importlib._bootstrap>", line 1467, in exec_module
  File "<frozen importlib._bootstrap>", line 1572, in get_code
  File "<frozen importlib._bootstrap>", line 1532, in source_to_code
  File "<frozen importlib._bootstrap>", line 321, in _call_with_frames_removed
  File "C:\TMV3\WorkingDir\DD_FSWT.py", line 75
    def set_StepTime(self,*par:'f0'):
      ^
SyntaxError: invalid syntax
09.04.2017 03:11:16 VI_ERROR_NLISTENERS (-1073807265): No listeners condition is detected (both NRFD and NDAC are deasserted). Meas
Traceback (most recent call last):
  File "C:\TMV3\DeviceDriver\DD_Analyzer.py", line 54, in checkConnection
    _ret = self.sa.query("*IDN?")
  File "C:\Python34\lib\site-packages\pyvisa\resources\messagebased.py", line 401, in query
    self.write(message)
  File "C:\Python34\lib\site-packages\pyvisa\resources\messagebased.py", line 207, in write
    count = self.write_raw(message.encode(enco))
  File "C:\Python34\lib\site-packages\pyvisa\resources\messagebased.py", line 185, in write_raw
    return self.visalib.write(self.session, message)
  File "C:\Python34\lib\site-packages\pyvisa\ctwrapper\functions.py", line 1864, in write
    ret = library.viWrite(session, data, len(data), byref(return_count))
  File "C:\Python34\lib\site-packages\pyvisa\ctwrapper\highlevel.py", line 188, in _return_handler
    raise errors.VisaIOError(ret_value)
pyvisa.errors.VisaIOError: VI_ERROR_NLISTENERS (-1073807265): No listeners condition is detected (both NRFD and NDAC are deasserted).
09.04.2017 03:11:19 recv 1fd1108 error WSAECONNRESET Server
09.04.2017 03:13:14 TMV3 Measurement started Meas
09.04.2017 03:13:16 -200,"Execution error;Function not available;SENSE:BAND:VID 100000000.0"
 Meas
09.04.2017 03:15:36 TMV3 Measurement started Meas
09.04.2017 03:15:38 -200,"Execution error;Function not available;SENSE:BAND:VID 100000000.0"
 Meas
09.04.2017 03:17:12 TMV3 Measurement started Meas
09.04.2017 03:17:15 -200,"Execution error;Function not available;SENSE:BAND:VID 100000000.0"
 Meas
09.04.2017 03:20:17 TMV3 Measurement started Meas
09.04.2017 03:20:19 -200,"Execution error;Function not available;SENSE:BAND:VID 100000000.0"
 Meas
09.04.2017 03:21:13 TMV3 Measurement started Meas
09.04.2017 03:21:16 -200,"Execution error;Function not available;SENSE:BAND:VID 100000000.0"
 Meas
09.04.2017 03:22:32 TMV3 Measurement started Meas
09.04.2017 03:22:34 -200,"Execution error;Function not available;SENSE:BAND:VID 100000000.0"
 Meas
09.04.2017 03:24:33 TMV3 Measurement started Meas
09.04.2017 03:24:36 unorderable types: str() > float() Meas
Traceback (most recent call last):
  File "C:\TMV3\Routines\RT_StandardHF.py", line 316, in startSetting
    _ret = _func(row.parameter)
  File "C:\TMV3\WorkingDir\DD_FSWT.py", line 69, in set_VidBW
    if _vf > 50e6:
TypeError: unorderable types: str() > float()
09.04.2017 03:25:15 TMV3 Measurement started Meas
09.04.2017 03:25:17 -200,"Execution error;Function not available;SENSE:BAND:VID 50000000.0"
 Meas
09.04.2017 03:28:46 TMV3 Measurement started Meas
09.04.2017 03:29:25 recv 2fd1640 error WSAECONNRESET Server
09.04.2017 03:29:26 recv 1fd1144 error WSAECONNRESET Server
09.04.2017 03:29:27 TMV3 Measurement started Meas
09.04.2017 03:30:22 -257,"File name error;CORR:TSET:DEL"
 Meas
09.06.2017 10:01:01 'ResourceManager' object has no attribute 'write'
Traceback (most recent call last):
  File "C:\TMV3\DeviceDriver\DD_Analyzer.py", line 70, in setup
    if not self.checkStatusCode(self.sa.write("*CLS")): return False      #Reset status reporting system
AttributeError: 'ResourceManager' object has no attribute 'write'
09.06.2017 10:03:21 VI_ERROR_RSRC_NFOUND (-1073807343): Insufficient location information or the requested device or resource is not present in the system.
Traceback (most recent call last):
  File "C:\TMV3\DeviceDriver\DD_Analyzer.py", line 52, in checkConnection
    self.sa = self.rm.open_resource(self.name)
  File "C:\Python34\lib\site-packages\pyvisa\highlevel.py", line 1623, in open_resource
    info = self.resource_info(resource_name, extended=True)
  File "C:\Python34\lib\site-packages\pyvisa\highlevel.py", line 1583, in resource_info
    ret, err = self.visalib.parse_resource_extended(self.session, resource_name)
  File "C:\Python34\lib\site-packages\pyvisa\ctwrapper\functions.py", line 1381, in parse_resource_extended
    alias_if_exists)
  File "C:\Python34\lib\site-packages\pyvisa\ctwrapper\highlevel.py", line 188, in _return_handler
    raise errors.VisaIOError(ret_value)
pyvisa.errors.VisaIOError: VI_ERROR_RSRC_NFOUND (-1073807343): Insufficient location information or the requested device or resource is not present in the system.
09.06.2017 10:06:07 'ResourceManager' object has no attribute 'write'
Traceback (most recent call last):
  File "C:\TMV3\DeviceDriver\DD_Analyzer.py", line 70, in setup
    if not self.checkStatusCode(self.sa.write("*CLS")): return False      #Reset status reporting system
AttributeError: 'ResourceManager' object has no attribute 'write'
09.06.2017 10:06:20 VI_ERROR_RSRC_NFOUND (-1073807343): Insufficient location information or the requested device or resource is not present in the system.
Traceback (most recent call last):
  File "C:\TMV3\DeviceDriver\DD_Analyzer.py", line 52, in checkConnection
    self.sa = self.rm.open_resource(self.name)
  File "C:\Python34\lib\site-packages\pyvisa\highlevel.py", line 1623, in open_resource
    info = self.resource_info(resource_name, extended=True)
  File "C:\Python34\lib\site-packages\pyvisa\highlevel.py", line 1583, in resource_info
    ret, err = self.visalib.parse_resource_extended(self.session, resource_name)
  File "C:\Python34\lib\site-packages\pyvisa\ctwrapper\functions.py", line 1381, in parse_resource_extended
    alias_if_exists)
  File "C:\Python34\lib\site-packages\pyvisa\ctwrapper\highlevel.py", line 188, in _return_handler
    raise errors.VisaIOError(ret_value)
pyvisa.errors.VisaIOError: VI_ERROR_RSRC_NFOUND (-1073807343): Insufficient location information or the requested device or resource is not present in the system.
09.06.2017 10:07:12 'ResourceManager' object has no attribute 'write'
Traceback (most recent call last):
  File "C:\TMV3\DeviceDriver\DD_Analyzer.py", line 70, in setup
    if not self.checkStatusCode(self.sa.write("*CLS")): return False      #Reset status reporting system
AttributeError: 'ResourceManager' object has no attribute 'write'
09.06.2017 10:09:01 VI_ERROR_RSRC_NFOUND (-1073807343): Insufficient location information or the requested device or resource is not present in the system.
Traceback (most recent call last):
  File "C:\TMV3\DeviceDriver\DD_Analyzer.py", line 52, in checkConnection
    self.sa = self.rm.open_resource(self.name)
  File "C:\Python34\lib\site-packages\pyvisa\highlevel.py", line 1623, in open_resource
    info = self.resource_info(resource_name, extended=True)
  File "C:\Python34\lib\site-packages\pyvisa\highlevel.py", line 1583, in resource_info
    ret, err = self.visalib.parse_resource_extended(self.session, resource_name)
  File "C:\Python34\lib\site-packages\pyvisa\ctwrapper\functions.py", line 1381, in parse_resource_extended
    alias_if_exists)
  File "C:\Python34\lib\site-packages\pyvisa\ctwrapper\highlevel.py", line 188, in _return_handler
    raise errors.VisaIOError(ret_value)
pyvisa.errors.VisaIOError: VI_ERROR_RSRC_NFOUND (-1073807343): Insufficient location information or the requested device or resource is not present in the system.
09.06.2017 10:10:08 VI_ERROR_RSRC_NFOUND (-1073807343): Insufficient location information or the requested device or resource is not present in the system.
Traceback (most recent call last):
  File "C:\TMV3\DeviceDriver\DD_Analyzer.py", line 52, in checkConnection
    self.sa = self.rm.open_resource(self.name)
  File "C:\Python34\lib\site-packages\pyvisa\highlevel.py", line 1623, in open_resource
    info = self.resource_info(resource_name, extended=True)
  File "C:\Python34\lib\site-packages\pyvisa\highlevel.py", line 1583, in resource_info
    ret, err = self.visalib.parse_resource_extended(self.session, resource_name)
  File "C:\Python34\lib\site-packages\pyvisa\ctwrapper\functions.py", line 1381, in parse_resource_extended
    alias_if_exists)
  File "C:\Python34\lib\site-packages\pyvisa\ctwrapper\highlevel.py", line 188, in _return_handler
    raise errors.VisaIOError(ret_value)
pyvisa.errors.VisaIOError: VI_ERROR_RSRC_NFOUND (-1073807343): Insufficient location information or the requested device or resource is not present in the system.
09.06.2017 10:27:56 'ResourceManager' object has no attribute 'write'
Traceback (most recent call last):
  File "C:\TMV3\DeviceDriver\DD_Analyzer.py", line 70, in setup
    if not self.checkStatusCode(self.sa.write("*CLS")): return False      #Reset status reporting system
AttributeError: 'ResourceManager' object has no attribute 'write'
09.06.2017 10:31:00 -200,"Execution error;Function not available;INP:GAIN:STATE ON"

09.06.2017 10:34:01 -200,"Execution error;Function not available;INP:GAIN:STATE ON"

09.06.2017 10:51:40 -200,"Execution error;Function not available;INP:GAIN:STATE ON"

09.06.2017 11:17:27 TMV3 Measurement started Meas
09.06.2017 11:17:29 name 'sFr' is not defined Meas
Traceback (most recent call last):
  File "C:\TMV3\Routines\RT_StandardHF.py", line 316, in startSetting
    _ret = _func(row.parameter)
  File "C:\TMV3\WorkingDir\DD_FSWT.py", line 35, in set_StartFreq
    return super().set_StartFreq(f)
  File "C:\TMV3\DeviceDriver\DD_Analyzer.py", line 319, in set_StartFreq
    print(sFr)
NameError: name 'sFr' is not defined
09.06.2017 11:19:06 TMV3 Measurement started Meas
09.06.2017 11:19:08 name 'sFr' is not defined Meas
Traceback (most recent call last):
  File "C:\TMV3\Routines\RT_StandardHF.py", line 316, in startSetting
    _ret = _func(row.parameter)
  File "C:\TMV3\WorkingDir\DD_FSWT.py", line 35, in set_StartFreq
    return super().set_StartFreq(f)
  File "C:\TMV3\DeviceDriver\DD_Analyzer.py", line 319, in set_StartFreq
    print(sFr)
NameError: name 'sFr' is not defined
09.06.2017 11:21:13 TMV3 Measurement started Meas
09.06.2017 11:22:25 recv 2fd1664 error WSAECONNRESET Server
09.06.2017 11:22:26 recv 1fd1128 error WSAECONNRESET Server
09.06.2017 11:22:27 TMV3 Measurement started Meas
09.06.2017 11:30:21 TMV3 Measurement started Meas
09.06.2017 12:03:10 recv 2fd1652 error WSAECONNRESET Server
09.07.2017 09:13:06 TMV3 Measurement started Meas
09.07.2017 09:13:11 VI_ERROR_TMO (-1073807339): Timeout expired before operation completed. Meas
Traceback (most recent call last):
  File "C:\TMV3\Routines\RT_StandardHF.py", line 437, in startTrace
    _ret, amp, att =  _func()
  File "C:\TMV3\WorkingDir\DD_FSWT.py", line 135, in autoRange
    if not (self.setAutoLevel()):
  File "C:\TMV3\WorkingDir\DD_FSWT.py", line 118, in setAutoLevel
    if not self.errorQueueHandler(): return False
  File "C:\TMV3\DeviceDriver\DD_Analyzer.py", line 154, in errorQueueHandler
    _error = self.sa.query("SYSTEM:ERROR?")
  File "C:\Python34\lib\site-packages\pyvisa\resources\messagebased.py", line 407, in query
    return self.read()
  File "C:\Python34\lib\site-packages\pyvisa\resources\messagebased.py", line 332, in read
    message = self.read_raw().decode(enco)
  File "C:\Python34\lib\site-packages\pyvisa\resources\messagebased.py", line 306, in read_raw
    chunk, status = self.visalib.read(self.session, size)
  File "C:\Python34\lib\site-packages\pyvisa\ctwrapper\functions.py", line 1582, in read
    ret = library.viRead(session, buffer, count, byref(return_count))
  File "C:\Python34\lib\site-packages\pyvisa\ctwrapper\highlevel.py", line 188, in _return_handler
    raise errors.VisaIOError(ret_value)
pyvisa.errors.VisaIOError: VI_ERROR_TMO (-1073807339): Timeout expired before operation completed.
09.07.2017 09:13:55 recv 2fd1644 error WSAECONNRESET Server
09.07.2017 09:16:03 TMV3 Measurement started Meas
09.07.2017 09:16:16 VI_ERROR_TMO (-1073807339): Timeout expired before operation completed. Meas
Traceback (most recent call last):
  File "C:\TMV3\Routines\RT_StandardHF.py", line 437, in startTrace
    _ret, amp, att =  _func()
  File "C:\TMV3\WorkingDir\DD_FSWT.py", line 136, in autoRange
    if not (self.setAutoLevel()):
  File "C:\TMV3\WorkingDir\DD_FSWT.py", line 118, in setAutoLevel
    if not self.errorQueueHandler(): return False
  File "C:\TMV3\DeviceDriver\DD_Analyzer.py", line 154, in errorQueueHandler
    _error = self.sa.query("SYSTEM:ERROR?")
  File "C:\Python34\lib\site-packages\pyvisa\resources\messagebased.py", line 407, in query
    return self.read()
  File "C:\Python34\lib\site-packages\pyvisa\resources\messagebased.py", line 332, in read
    message = self.read_raw().decode(enco)
  File "C:\Python34\lib\site-packages\pyvisa\resources\messagebased.py", line 306, in read_raw
    chunk, status = self.visalib.read(self.session, size)
  File "C:\Python34\lib\site-packages\pyvisa\ctwrapper\functions.py", line 1582, in read
    ret = library.viRead(session, buffer, count, byref(return_count))
  File "C:\Python34\lib\site-packages\pyvisa\ctwrapper\highlevel.py", line 188, in _return_handler
    raise errors.VisaIOError(ret_value)
pyvisa.errors.VisaIOError: VI_ERROR_TMO (-1073807339): Timeout expired before operation completed.
09.07.2017 09:23:18 TMV3 Measurement started Meas
09.07.2017 09:23:32 VI_ERROR_TMO (-1073807339): Timeout expired before operation completed. Meas
Traceback (most recent call last):
  File "C:\TMV3\Routines\RT_StandardHF.py", line 437, in startTrace
    _ret, amp, att =  _func()
  File "C:\TMV3\WorkingDir\DD_FSWT.py", line 136, in autoRange
    if not (self.setAutoLevel()):
  File "C:\TMV3\WorkingDir\DD_FSWT.py", line 118, in setAutoLevel
    if not self.errorQueueHandler(): return False
  File "C:\TMV3\DeviceDriver\DD_Analyzer.py", line 154, in errorQueueHandler
    _error = self.sa.query("SYSTEM:ERROR?")
  File "C:\Python34\lib\site-packages\pyvisa\resources\messagebased.py", line 407, in query
    return self.read()
  File "C:\Python34\lib\site-packages\pyvisa\resources\messagebased.py", line 332, in read
    message = self.read_raw().decode(enco)
  File "C:\Python34\lib\site-packages\pyvisa\resources\messagebased.py", line 306, in read_raw
    chunk, status = self.visalib.read(self.session, size)
  File "C:\Python34\lib\site-packages\pyvisa\ctwrapper\functions.py", line 1582, in read
    ret = library.viRead(session, buffer, count, byref(return_count))
  File "C:\Python34\lib\site-packages\pyvisa\ctwrapper\highlevel.py", line 188, in _return_handler
    raise errors.VisaIOError(ret_value)
pyvisa.errors.VisaIOError: VI_ERROR_TMO (-1073807339): Timeout expired before operation completed.
09.07.2017 09:24:29 TMV3 Measurement started Meas
09.07.2017 09:24:42 VI_ERROR_TMO (-1073807339): Timeout expired before operation completed. Meas
Traceback (most recent call last):
  File "C:\TMV3\Routines\RT_StandardHF.py", line 437, in startTrace
    _ret, amp, att =  _func()
  File "C:\TMV3\WorkingDir\DD_FSWT.py", line 136, in autoRange
    if not (self.setAutoLevel()):
  File "C:\TMV3\WorkingDir\DD_FSWT.py", line 118, in setAutoLevel
    if not self.errorQueueHandler(): return False
  File "C:\TMV3\DeviceDriver\DD_Analyzer.py", line 154, in errorQueueHandler
    _error = self.sa.query("SYSTEM:ERROR?")
  File "C:\Python34\lib\site-packages\pyvisa\resources\messagebased.py", line 407, in query
    return self.read()
  File "C:\Python34\lib\site-packages\pyvisa\resources\messagebased.py", line 332, in read
    message = self.read_raw().decode(enco)
  File "C:\Python34\lib\site-packages\pyvisa\resources\messagebased.py", line 306, in read_raw
    chunk, status = self.visalib.read(self.session, size)
  File "C:\Python34\lib\site-packages\pyvisa\ctwrapper\functions.py", line 1582, in read
    ret = library.viRead(session, buffer, count, byref(return_count))
  File "C:\Python34\lib\site-packages\pyvisa\ctwrapper\highlevel.py", line 188, in _return_handler
    raise errors.VisaIOError(ret_value)
pyvisa.errors.VisaIOError: VI_ERROR_TMO (-1073807339): Timeout expired before operation completed.
09.07.2017 09:25:51 TMV3 Measurement started Meas
09.07.2017 09:25:56 VI_ERROR_TMO (-1073807339): Timeout expired before operation completed. Meas
Traceback (most recent call last):
  File "C:\TMV3\Routines\RT_StandardHF.py", line 437, in startTrace
    _ret, amp, att =  _func()
  File "C:\TMV3\WorkingDir\DD_FSWT.py", line 136, in autoRange
    if not (self.setAutoLevel()):
  File "C:\TMV3\WorkingDir\DD_FSWT.py", line 118, in setAutoLevel
    if not self.errorQueueHandler(): return False
  File "C:\TMV3\DeviceDriver\DD_Analyzer.py", line 154, in errorQueueHandler
    _error = self.sa.query("SYSTEM:ERROR?")
  File "C:\Python34\lib\site-packages\pyvisa\resources\messagebased.py", line 407, in query
    return self.read()
  File "C:\Python34\lib\site-packages\pyvisa\resources\messagebased.py", line 332, in read
    message = self.read_raw().decode(enco)
  File "C:\Python34\lib\site-packages\pyvisa\resources\messagebased.py", line 306, in read_raw
    chunk, status = self.visalib.read(self.session, size)
  File "C:\Python34\lib\site-packages\pyvisa\ctwrapper\functions.py", line 1582, in read
    ret = library.viRead(session, buffer, count, byref(return_count))
  File "C:\Python34\lib\site-packages\pyvisa\ctwrapper\highlevel.py", line 188, in _return_handler
    raise errors.VisaIOError(ret_value)
pyvisa.errors.VisaIOError: VI_ERROR_TMO (-1073807339): Timeout expired before operation completed.
09.07.2017 09:32:51 TMV3 Measurement started Meas
09.07.2017 09:50:49 TMV3 Measurement started Meas
09.07.2017 09:51:49 TMV3 Measurement started Meas
09.07.2017 09:55:27 TMV3 Measurement started Meas
09.07.2017 09:55:31 Can't convert 'int' object to str implicitly Meas
Traceback (most recent call last):
  File "C:\TMV3\Routines\RT_StandardHF.py", line 437, in startTrace
    _ret, amp, att =  _func()
  File "C:\TMV3\WorkingDir\DD_FSWT.py", line 143, in autoRange
    super().take_Sweep(sw)
  File "C:\TMV3\DeviceDriver\DD_Analyzer.py", line 213, in take_Sweep
    _timeout = s*1000 + 2000 # sweeptime[ms] + spare
TypeError: Can't convert 'int' object to str implicitly
09.07.2017 09:56:36 TMV3 Measurement started Meas
09.07.2017 10:09:34 TMV3 Measurement started Meas
09.07.2017 10:16:00 TMV3 Measurement started Meas
09.07.2017 10:20:49 TMV3 Measurement started Meas
09.07.2017 10:22:27 recv 2fd1628 error WSAECONNRESET Server
09.07.2017 10:22:28 recv 1fd1596 error WSAECONNRESET Server
09.07.2017 10:22:28 TMV3 Measurement started Meas
09.07.2017 10:24:00 recv 4fd1920 error WSAECONNRESET Server
09.07.2017 10:24:01 recv 3fd1592 error WSAECONNRESET Server
09.07.2017 10:24:01 TMV3 Measurement started Meas
09.07.2017 10:26:14 recv 6fd1860 error WSAECONNRESET Server
09.07.2017 10:26:15 recv 5fd1632 error WSAECONNRESET Server
09.07.2017 10:26:15 TMV3 Measurement started Meas
09.07.2017 10:27:50 recv 8fd1652 error WSAECONNRESET Server
09.07.2017 10:27:51 recv 7fd1900 error WSAECONNRESET Server
09.07.2017 10:27:52 TMV3 Measurement started Meas
09.07.2017 10:29:29 recv 10fd1844 error WSAECONNRESET Server
09.07.2017 10:29:30 recv 9fd1856 error WSAECONNRESET Server
09.07.2017 10:29:31 TMV3 Measurement started Meas
09.07.2017 10:37:13 recv 12fd1944 error WSAECONNRESET Server
09.07.2017 10:40:12 TMV3 Measurement started Meas
09.07.2017 10:46:14 recv 2fd1644 error WSAECONNRESET Server
09.07.2017 10:46:15 recv 1fd1124 error WSAECONNRESET Server
09.07.2017 10:46:15 TMV3 Measurement started Meas
09.07.2017 10:52:20 recv 4fd1608 error WSAECONNRESET Server
09.07.2017 10:52:21 recv 3fd1612 error WSAECONNRESET Server
09.07.2017 10:52:21 TMV3 Measurement started Meas
09.07.2017 10:56:56 recv 6fd1912 error WSAECONNRESET Server
09.07.2017 10:56:57 recv 5fd1124 error WSAECONNRESET Server
09.07.2017 10:56:57 TMV3 Measurement started Meas
09.07.2017 10:57:37 recv 8fd1932 error WSAECONNRESET Server
09.07.2017 10:57:38 recv 7fd1612 error WSAECONNRESET Server
09.07.2017 10:57:39 TMV3 Measurement started Meas
09.07.2017 11:37:51 recv 10fd1896 error WSAECONNRESET Server
09.11.2017 09:30:19 TMV3 Measurement started Meas
09.11.2017 09:30:22 VI_ERROR_RSRC_NFOUND (-1073807343): Insufficient location information or the requested device or resource is not present in the system. Meas
Traceback (most recent call last):
  File "C:\TMV3\DeviceDriver\DD_Analyzer.py", line 52, in checkConnection
    self.sa = self.rm.open_resource(self.name)
  File "C:\Python34\lib\site-packages\pyvisa\highlevel.py", line 1623, in open_resource
    info = self.resource_info(resource_name, extended=True)
  File "C:\Python34\lib\site-packages\pyvisa\highlevel.py", line 1583, in resource_info
    ret, err = self.visalib.parse_resource_extended(self.session, resource_name)
  File "C:\Python34\lib\site-packages\pyvisa\ctwrapper\functions.py", line 1381, in parse_resource_extended
    alias_if_exists)
  File "C:\Python34\lib\site-packages\pyvisa\ctwrapper\highlevel.py", line 188, in _return_handler
    raise errors.VisaIOError(ret_value)
pyvisa.errors.VisaIOError: VI_ERROR_RSRC_NFOUND (-1073807343): Insufficient location information or the requested device or resource is not present in the system.
09.11.2017 09:30:22 VI_ERROR_BERR (-1073807304): Bus error occurred during transfer. Meas
Traceback (most recent call last):
  File "C:\TMV3\DeviceDriver\DD_Analyzer.py", line 52, in checkConnection
    self.sa = self.rm.open_resource(self.name)
  File "C:\Python34\lib\site-packages\pyvisa\highlevel.py", line 1644, in open_resource
    res.open(access_mode, open_timeout)
  File "C:\Python34\lib\site-packages\pyvisa\resources\resource.py", line 215, in open
    self.clear()
  File "C:\Python34\lib\site-packages\pyvisa\resources\resource.py", line 270, in clear
    self.visalib.clear(self.session)
  File "C:\Python34\lib\site-packages\pyvisa\ctwrapper\functions.py", line 379, in clear
    return library.viClear(session)
  File "C:\Python34\lib\site-packages\pyvisa\ctwrapper\highlevel.py", line 188, in _return_handler
    raise errors.VisaIOError(ret_value)
pyvisa.errors.VisaIOError: VI_ERROR_BERR (-1073807304): Bus error occurred during transfer.
09.11.2017 09:30:27 recv 1fd1140 error WSAECONNRESET Server
09.11.2017 09:32:20 TMV3 Measurement started Meas
09.11.2017 09:33:34 recv 2fd1648 error WSAECONNRESET Server
09.11.2017 09:33:35 recv 1fd1128 error WSAECONNRESET Server
09.11.2017 09:33:35 TMV3 Measurement started Meas
09.11.2017 09:33:38 VI_ERROR_BERR (-1073807304): Bus error occurred during transfer. Meas
Traceback (most recent call last):
  File "C:\TMV3\DeviceDriver\DD_Relais.py", line 34, in checkConnection
    self.rl = self.rm.open_resource(self.name)
  File "C:\Python34\lib\site-packages\pyvisa\highlevel.py", line 1644, in open_resource
    res.open(access_mode, open_timeout)
  File "C:\Python34\lib\site-packages\pyvisa\resources\resource.py", line 215, in open
    self.clear()
  File "C:\Python34\lib\site-packages\pyvisa\resources\resource.py", line 270, in clear
    self.visalib.clear(self.session)
  File "C:\Python34\lib\site-packages\pyvisa\ctwrapper\functions.py", line 379, in clear
    return library.viClear(session)
  File "C:\Python34\lib\site-packages\pyvisa\ctwrapper\highlevel.py", line 188, in _return_handler
    raise errors.VisaIOError(ret_value)
pyvisa.errors.VisaIOError: VI_ERROR_BERR (-1073807304): Bus error occurred during transfer.
09.11.2017 10:34:01 recv 3fd1616 error WSAECONNRESET Server
